Workbook

Sheet 완제품
A1: BF 제품 회전율 현황 (완제품) | H1: =TODAY() -> 45803 | S1: 회전등급
S2: A | T2: B | V2: C
S3: 회전월 =< 1 | T3: 1 < 회전월 =< 4 | V3: 회전월 > 4
S4: * 저회전 : 회전율 0.1 미만
D6: 재고 | H6: 출고 | O6: 생산 | S6: 재고분석 | W6: 월 생산량(2025) | AH6: 단위 : kg | AI6: 월별 출고량(2024) | AU6: 월별 출고량(2025) | BG6: 월말 재고량(2024) | BS6: 월말 재고량(2025) | CE6: 월 회전율 (2024) | CQ6: 월 회전율 (2025)
A7: 구분 | B7: 품목 | C7: 품목명 | D7: 규격 | E7: 원가(원) | F7: 현재고 | G7: 재고금액(원) | H7: 월 출고량 | I7: 회전월 | J7: 예상 소진일 | K7: 소비기한 | L7: 생산리드타임 | M7: 출고가능일 | N7: 수율 | O7: 생산필요 | P7: 생산량(kg) | Q7: 생산량(ea) | R7: 추가 소진일 | S7: 소진가능여부 | T7: 회전등급 | U7: 저회전 발생 | V7: 재고평가 | W7: 1 | X7: =+W7+1 -> 2 | Y7: =+X7+1 -> 3 | Z7: =+Y7+1 -> 4 | AA7: =+Z7+1 -> 5 | AB7: =+AA7+1 -> 6 | AC7: =+AB7+1 -> 7 | AD7: =+AC7+1 -> 8 | AE7: =+AD7+1 -> 9 | ... AH7: =+AG7+1 -> 12 | AI7: 1 | AJ7: =+AI7+1 -> 2 | AK7: =+AJ7+1 -> 3 | AL7: =+AK7+1 -> 4 | AM7: =+AL7+1 -> 5 | AN7: =+AM7+1 -> 6 | AO7: =+AN7+1 -> 7 | AP7: =+AO7+1 -> 8 | AQ7: =+AP7+1 -> 9 | ... AT7: =+AS7+1 -> 12 | AU7: 1 | AV7: =+AU7+1 -> 2 | AW7: =+AV7+1 -> 3 | AX7: =+AW7+1 -> 4 | AY7: =+AX7+1 -> 5 | AZ7: =+AY7+1 -> 6 | BA7: =+AZ7+1 -> 7 | BB7: =+BA7+1 -> 8 | BC7: =+BB7+1 -> 9 | ... BF7: =+BE7+1 -> 12 | BG7: 1 | BH7: =+BG7+1 -> 2 | BI7: =+BH7+1 -> 3 | BJ7: =+BI7+1 -> 4 | BK7: =+BJ7+1 -> 5 | BL7: =+BK7+1 -> 6 | BM7: =+BL7+1 -> 7 | BN7: =+BM7+1 -> 8 | BO7: =+BN7+1 -> 9 | ... BR7: =+BQ7+1 -> 12 | BS7: 1 | BT7: =+BS7+1 -> 2 | BU7: =+BT7+1 -> 3 | BV7: =+BU7+1 -> 4 | BW7: =+BV7+1 -> 5 | BX7: =+BW7+1 -> 6 | BY7: =+BX7+1 -> 7 | BZ7: =+BY7+1 -> 8 | CA7: =+BZ7+1 -> 9 | ... CD7: =+CC7+1 -> 12 | CE7: 1 | CF7: =+CE7+1 -> 2 | CG7: =+CF7+1 -> 3 | CH7: =+CG7+1 -> 4 | CI7: =+CH7+1 -> 5 | CJ7: =+CI7+1 -> 6 | CK7: =+CJ7+1 -> 7 | CL7: =+CK7+1 -> 8 | CM7: =+CL7+1 -> 9 | ... CP7: =+CO7+1 -> 12 | CQ7: 1 | CR7: =+CQ7+1 -> 2 | CS7: =+CR7+1 -> 3 | CT7: =+CS7+1 -> 4 | CU7: =+CT7+1 -> 5 | CV7: =+CU7+1 -> 6 | CW7: =+CV7+1 -> 7 | CX7: =+CW7+1 -> 8 | CY7: =+CX7+1 -> 9 | ... DB7: =+DA7+1 -> 12
A8: 완제품 | B8: 325230 | C8: YWE 식물성 콜드컷 볼로냐 (국내) | D8: 0.5 | E8: =IFERROR(VLOOKUP(B8,재고DB!H:AS,38,FALSE),0) -> 4800 | F8: =SUMIF(재고DB!$H:$H,완제품!$B8,재고DB!$AB:$AB) -> 1526 | G8: =+E8*F8 -> 7324800 | H8: =IFERROR(VLOOKUP(B8,출고량!$A:$D,4,FALSE),0) -> 141.3871 | I8: =IFERROR(F8/H8,0) -> 10.793064 | J8: =IF(F8=0,"재고없음",IF(H8=0,"출고없음",$H$1+I8*30)) -> 46126.792 | K8: =IF(F8=0,"재고없음",IFERROR(VLOOKUP(B8,재고DB!H:BU,66,FALSE),0)) -> 45924 | L8: 28 | M8: =+L8+$H$1 -> 45831 | N8: 0.9 | O8: =IFERROR(IF(M8-J8>0,"O","X"),"없음") -> X | P8: 0 | Q8: =+P8/D8*N8 -> 0 | R8: =IFERROR((Q8+F8)/H8*30+$H$1,"없음") -> 46126.792 | S8: =IFERROR(IF(J8="출고없음","X",IF(K8-J8>0,"O","X")),0) -> X | T8: =IF(J8="출고없음",$V$2,IF(I8=0,"-",IF(I8<=1,$S$2,IF(AND(I8>1,I8<=4),$T$2,$V$2)))) -> C | U8: =COUNTIF(CH8:CS8,"<0.1")+COUNTIF(CH8:CS8,"=미출고") -> 3 | V8: =IF(AND(S8="X",T8="C",U8>4),"단산검토",IF(AND(S8="X",T8="C"),"소진계획필요","판매활성화")) -> 소진계획필요 | X8: 300 | AI8: 0 | AJ8: 0 | AK8: 0 | AL8: 0 | AM8: 0 | AN8: 24 | AO8: 612 | AP8: 3295 | AQ8: 3616 | AR8: 3050 | AS8: 243 | AT8: 219 | AU8: 176 | AV8: 141 | AW8: 525 | AX8: 141 | BG8: 0 | BH8: 0 | BI8: 0 | BJ8: 0 | BK8: 0 | BL8: 876 | BM8: 2234 | BN8: 2625 | BO8: 1931 | BP8: 2005 | BQ8: 2292 | BR8: 2073 | BS8: 1855 | BT8: 1713 | BU8: 1750 | CE8: =IF(AND(AI8=0,BG8=0),"출시전",IF(AND(AI8=0,BG8>0),"미출고",AI8/BG8)) -> 출시전 | CF8: =IF(AND(AJ8=0,BH8=0),"출시전",IF(AND(AJ8=0,BH8>0),"미출고",AJ8/BH8)) -> 출시전 | CG8: =IF(AND(AK8=0,BI8=0),"출시전",IF(AND(AK8=0,BI8>0),"미출고",AK8/BI8)) -> 출시전 | CH8: =IF(AND(AL8=0,BJ8=0),"출시전",IF(AND(AL8=0,BJ8>0),"미출고",AL8/BJ8)) -> 출시전 | CI8: =IF(AND(AM8=0,BK8=0),"출시전",IF(AND(AM8=0,BK8>0),"미출고",AM8/BK8)) -> 출시전 | CJ8: =IF(AND(AN8=0,BL8=0),"출시전",IF(AND(AN8=0,BL8>0),"미출고",AN8/BL8)) -> 0.02739726 | CK8: =IF(AND(AO8=0,BM8=0),"출시전",IF(AND(AO8=0,BM8>0),"미출고",AO8/BM8)) -> 0.27394808 | CL8: =IF(AND(AP8=0,BN8=0),"출시전",IF(AND(AP8=0,BN8>0),"미출고",AP8/BN8)) -> 1.2552381 | ... CS8: =IF(AND(AW8=0,BU8=0),"출시전",IF(AND(AW8=0,BU8>0),"미출고",AW8/BU8)) -> 0.3
A9: 완제품 | B9: 259276 | C9: 베러미트 식물성 프랑크 소시지 | D9: 1.05 | E9: =IFERROR(VLOOKUP(B9,재고DB!H:AS,38,FALSE),0) -> 11568 | F9: =SUMIF(재고DB!$H:$H,완제품!$B9,재고DB!$AB:$AB)+2500 -> 3868 | G9: =+E9*F9 -> 44745024 | H9: =IFERROR(VLOOKUP(B9,출고량!$A:$D,4,FALSE),0) -> 2803.0645 | I9: =IFERROR(F9/H9,0) -> 1.3799183 | J9: =IF(F9=0,"재고없음",IF(H9=0,"출고없음",$H$1+I9*30)) -> 45844.398 | K9: =IF(F9=0,"재고없음",IFERROR(VLOOKUP(B9,재고DB!H:BU,66,FALSE),0)) -> 46032 | L9: 28 | M9: =+L9+$H$1 -> 45831 | N9: 0.88 | O9: =IFERROR(IF(M9-J9>0,"O","X"),"없음") -> X | Q9: =+P9/D9*N9 -> 0 | R9: =IFERROR((Q9+F9)/H9*30+$H$1,"없음") -> 45844.398 | S9: =IFERROR(IF(J9="출고없음","X",IF(K9-J9>0,"O","X")),0) -> O | T9: =IF(J9="출고없음",$V$2,IF(I9=0,"-",IF(I9<=1,$S$2,IF(AND(I9>1,I9<=4),$T$2,$V$2)))) -> B | U9: =COUNTIF(CH9:CS9,"<0.1")+COUNTIF(CH9:CS9,"=미출고") -> 0 | V9: =IF(AND(S9="X",T9="C",U9>4),"단산검토",IF(AND(S9="X",T9="C"),"소진계획필요","판매활성화")) -> 판매활성화 | X9: 2000 | Y9: 2000 | Z9: 2000 | AI9: 3101 | AJ9: 2525 | AK9: 2931 | AL9: 3244 | AM9: 3192 | AN9: 3279 | AO9: 3650 | AP9: 3764 | AQ9: 3201 | AR9: 3118 | AS9: 2613 | AT9: 2691 | AU9: 2926 | AV9: 2191 | AW9: 2545 | AX9: 2581 | BG9: 3920 | BH9: 3030 | BI9: 3218 | BJ9: 3946 | BK9: 3358 | BL9: 1942 | BM9: 3202 | BN9: 2828 | BO9: 4471 | BP9: 3746 | BQ9: 4422 | BR9: 1738 | BS9: 2291 | BT9: 1806 | BU9: 1087 | CE9: =IF(AND(AI9=0,BG9=0),"출시전",IF(AND(AI9=0,BG9>0),"미출고",AI9/BG9)) -> 0.79107143 | CF9: =IF(AND(AJ9=0,BH9=0),"출시전",IF(AND(AJ9=0,BH9>0),"미출고",AJ9/BH9)) -> 0.83333333 | CG9: =IF(AND(AK9=0,BI9=0),"출시전",IF(AND(AK9=0,BI9>0),"미출고",AK9/BI9)) -> 0.91081417 | CH9: =IF(AND(AL9=0,BJ9=0),"출시전",IF(AND(AL9=0,BJ9>0),"미출고",AL9/BJ9)) -> 0.82209833 | CI9: =IF(AND(AM9=0,BK9=0),"출시전",IF(AND(AM9=0,BK9>0),"미출고",AM9/BK9)) -> 0.95056581 | CJ9: =IF(AND(AN9=0,BL9=0),"출시전",IF(AND(AN9=0,BL9>0),"미출고",AN9/BL9)) -> 1.6884655 | CK9: =IF(AND(AO9=0,BM9=0),"출시전",IF(AND(AO9=0,BM9>0),"미출고",AO9/BM9)) -> 1.1399126 | CL9: =IF(AND(AP9=0,BN9=0),"출시전",IF(AND(AP9=0,BN9>0),"미출고",AP9/BN9)) -> 1.330976 | ... CS9: =IF(AND(AW9=0,BU9=0),"출시전",IF(AND(AW9=0,BU9>0),"미출고",AW9/BU9)) -> 2.3413063
A10: 완제품 | B10: 321731 | C10: 베러미트 그릴드 프랑크 소시지 | D10: 1.05 | E10: =IFERROR(VLOOKUP(B10,재고DB!H:AS,38,FALSE),0) -> 0 | F10: =SUMIF(재고DB!$H:$H,완제품!$B10,재고DB!$AB:$AB) -> 0 | G10: =+E10*F10 -> 0 | H10: =IFERROR(VLOOKUP(B10,출고량!$A:$D,4,FALSE),0) -> 0 | I10: =IFERROR(F10/H10,0) -> 0 | J10: =IF(F10=0,"재고없음",IF(H10=0,"출고없음",$H$1+I10*30)) -> 재고없음 | K10: =IF(F10=0,"재고없음",IFERROR(VLOOKUP(B10,재고DB!H:BU,66,FALSE),0)) -> 재고없음 | L10: 0 | M10: =+L10+$H$1 -> 45803 | N10: 0.86 | O10: =IFERROR(IF(M10-J10>0,"O","X"),"없음") -> 없음 | P10: 0 | Q10: =+P10/D10*N10 -> 0 | R10: =IFERROR((Q10+F10)/H10*30+$H$1,"없음") -> 없음 | S10: =IFERROR(IF(J10="출고없음","X",IF(K10-J10>0,"O","X")),0) -> 0 | T10: =IF(J10="출고없음",$V$2,IF(I10=0,"-",IF(I10<=1,$S$2,IF(AND(I10>1,I10<=4),$T$2,$V$2)))) -> - | U10: =COUNTIF(CH10:CS10,"<0.1")+COUNTIF(CH10:CS10,"=미출고") -> 5 | V10: =IF(AND(S10="X",T10="C",U10>4),"단산검토",IF(AND(S10="X",T10="C"),"소진계획필요","판매활성화")) -> 판매활성화 | AI10: 0 | AJ10: 0 | AK10: 44 | AL10: 3 | AM10: 1 | AN10: 5 | AO10: 17 | AP10: 2 | AQ10: 1 | AR10: 49 | AS10: 0 | AT10: 0 | AU10: 0 | AV10: 0 | AW10: 0 | AX10: 0 | BG10: 0 | BH10: 120 | BI10: 77 | BJ10: 73 | BK10: 70 | BL10: 65 | BM10: 48 | BN10: 46 | BO10: 46 | BP10: 49 | BQ10: 0 | BR10: 0 | BS10: 0 | BT10: 0 | BU10: 0 | CE10: =IF(AND(AI10=0,BG10=0),"출시전",IF(AND(AI10=0,BG10>0),"미출고",AI10/BG10)) -> 출시전 | CF10: =IF(AND(AJ10=0,BH10=0),"출시전",IF(AND(AJ10=0,BH10>0),"미출고",AJ10/BH10)) -> 미출고 | CG10: =IF(AND(AK10=0,BI10=0),"출시전",IF(AND(AK10=0,BI10>0),"미출고",AK10/BI10)) -> 0.57142857 | CH10: =IF(AND(AL10=0,BJ10=0),"출시전",IF(AND(AL10=0,BJ10>0),"미출고",AL10/BJ10)) -> 0.04109589 | CI10: =IF(AND(AM10=0,BK10=0),"출시전",IF(AND(AM10=0,BK10>0),"미출고",AM10/BK10)) -> 0.014285714 | CJ10: =IF(AND(AN10=0,BL10=0),"출시전",IF(AND(AN10=0,BL10>0),"미출고",AN10/BL10)) -> 0.076923077 | CK10: =IF(AND(AO10=0,BM10=0),"출시전",IF(AND(AO10=0,BM10>0),"미출고",AO10/BM10)) -> 0.35416667 | CL10: =IF(AND(AP10=0,BN10=0),"출시전",IF(AND(AP10=0,BN10>0),"미출고",AP10/BN10)) -> 0.043478261 | ... CS10: =IF(AND(AW10=0,BU10=0),"출시전",IF(AND(AW10=0,BU10>0),"미출고",AW10/BU10)) -> 출시전
A11: 완제품 | B11: 326323 | C11: 리얼 민스 | D11: 5 | E11: =IFERROR(VLOOKUP(B11,재고DB!H:AS,38,FALSE),0) -> 0 | F11: =SUMIF(재고DB!$H:$H,완제품!$B11,재고DB!$AB:$AB) -> 0 | G11: =+E11*F11 -> 0 | H11: =IFERROR(VLOOKUP(B11,출고량!$A:$D,4,FALSE),0) -> 15.225806 | I11: =IFERROR(F11/H11,0) -> 0 | J11: =IF(F11=0,"재고없음",IF(H11=0,"출고없음",$H$1+I11*30)) -> 재고없음 | K11: =IF(F11=0,"재고없음",IFERROR(VLOOKUP(B11,재고DB!H:BU,66,FALSE),0)) -> 재고없음 | L11: 0 | M11: =+L11+$H$1 -> 45803 | N11: 0.86 | O11: =IFERROR(IF(M11-J11>0,"O","X"),"없음") -> 없음 | P11: 0 | Q11: =+P11/D11*N11 -> 0 | R11: =IFERROR((Q11+F11)/H11*30+$H$1,"없음") -> 45803 | S11: =IFERROR(IF(J11="출고없음","X",IF(K11-J11>0,"O","X")),0) -> 0 | T11: =IF(J11="출고없음",$V$2,IF(I11=0,"-",IF(I11<=1,$S$2,IF(AND(I11>1,I11<=4),$T$2,$V$2)))) -> - | U11: =COUNTIF(CH11:CS11,"<0.1")+COUNTIF(CH11:CS11,"=미출고") -> 3 | V11: =IF(AND(S11="X",T11="C",U11>4),"단산검토",IF(AND(S11="X",T11="C"),"소진계획필요","판매활성화")) -> 판매활성화 | AI11: 0 | AJ11: 0 | AK11: 0 | AL11: 0 | AM11: 0 | AN11: 1 | AO11: 8 | AP11: 98 | AQ11: 40 | AR11: 106 | AS11: 104 | AT11: 0 | AU11: 64 | AV11: 0 | AW11: 52 | AX11: 59 | BG11: 0 | BH11: 0 | BI11: 0 | BJ11: 0 | BK11: 0 | BL11: 17 | BM11: 9 | BN11: 107 | BO11: 67 | BP11: 226 | BQ11: 174 | BR11: 174 | BS11: 110 | BT11: 110 | BU11: 59 | CE11: =IF(AND(AI11=0,BG11=0),"출시전",IF(AND(AI11=0,BG11>0),"미출고",AI11/BG11)) -> 출시전 | CF11: =IF(AND(AJ11=0,BH11=0),"출시전",IF(AND(AJ11=0,BH11>0),"미출고",AJ11/BH11)) -> 출시전 | CG11: =IF(AND(AK11=0,BI11=0),"출시전",IF(AND(AK11=0,BI11>0),"미출고",AK11/BI11)) -> 출시전 | CH11: =IF(AND(AL11=0,BJ11=0),"출시전",IF(AND(AL11=0,BJ11>0),"미출고",AL11/BJ11)) -> 출시전 | CI11: =IF(AND(AM11=0,BK11=0),"출시전",IF(AND(AM11=0,BK11>0),"미출고",AM11/BK11)) -> 출시전 | CJ11: =IF(AND(AN11=0,BL11=0),"출시전",IF(AND(AN11=0,BL11>0),"미출고",AN11/BL11)) -> 0.058823529 | CK11: =IF(AND(AO11=0,BM11=0),"출시전",IF(AND(AO11=0,BM11>0),"미출고",AO11/BM11)) -> 0.88888889 | CL11: =IF(AND(AP11=0,BN11=0),"출시전",IF(AND(AP11=0,BN11>0),"미출고",AP11/BN11)) -> 0.91588785 | ... CS11: =IF(AND(AW11=0,BU11=0),"출시전",IF(AND(AW11=0,BU11>0),"미출고",AW11/BU11)) -> 0.88135593
A12: 완제품 | B12: 333524 | C12: 유아왓유잇 식물성 너겟 | D12: 1 | E12: =IFERROR(VLOOKUP(B12,재고DB!H:AS,38,FALSE),0) -> 6883 | F12: =SUMIF(재고DB!$H:$H,완제품!$B12,재고DB!$AB:$AB) -> 1762 | G12: =+E12*F12 -> 12127846 | H12: =IFERROR(VLOOKUP(B12,출고량!$A:$D,4,FALSE),0) -> 74.419355 | I12: =IFERROR(F12/H12,0) -> 23.676636 | J12: =IF(F12=0,"재고없음",IF(H12=0,"출고없음",$H$1+I12*30)) -> 46513.299 | K12: =IF(F12=0,"재고없음",IFERROR(VLOOKUP(B12,재고DB!H:BU,66,FALSE),0)) -> 45878 | L12: 42 | M12: =+L12+$H$1 -> 45845 | N12: 0.9 | O12: =IFERROR(IF(M12-J12>0,"O","X"),"없음") -> X | P12: 0 | Q12: =+P12/D12*N12 -> 0 | R12: =IFERROR((Q12+F12)/H12*30+$H$1,"없음") -> 46513.299 | S12: =IFERROR(IF(J12="출고없음","X",IF(K12-J12>0,"O","X")),0) -> X | T12: =IF(J12="출고없음",$V$2,IF(I12=0,"-",IF(I12<=1,$S$2,IF(AND(I12>1,I12<=4),$T$2,$V$2)))) -> C | U12: =COUNTIF(CH12:CS12,"<0.1")+COUNTIF(CH12:CS12,"=미출고") -> 6 | V12: =IF(AND(S12="X",T12="C",U12>4),"단산검토",IF(AND(S12="X",T12="C"),"소진계획필요","판매활성화")) -> 단산검토 | AI12: 0 | AJ12: 0 | AK12: 0 | AL12: 0 | AM12: 0 | AN12: 0 | AO12: 0 | AP12: 11 | AQ12: 20 | AR12: 174 | AS12: 293 | AT12: 314 | AU12: 23 | AV12: 38 | AW12: 134 | AX12: 114 | BG12: 0 | BH12: 0 | BI12: 0 | BJ12: 0 | BK12: 0 | BL12: 0 | BM12: 0 | BN12: 2917 | BO12: 2897 | BP12: 2707 | BQ12: 2430 | BR12: 2116 | BS12: 2060 | BT12: 2009 | BU12: 1921 | CE12: =IF(AND(AI12=0,BG12=0),"출시전",IF(AND(AI12=0,BG12>0),"미출고",AI12/BG12)) -> 출시전 | CF12: =IF(AND(AJ12=0,BH12=0),"출시전",IF(AND(AJ12=0,BH12>0),"미출고",AJ12/BH12)) -> 출시전 | CG12: =IF(AND(AK12=0,BI12=0),"출시전",IF(AND(AK12=0,BI12>0),"미출고",AK12/BI12)) -> 출시전 | CH12: =IF(AND(AL12=0,BJ12=0),"출시전",IF(AND(AL12=0,BJ12>0),"미출고",AL12/BJ12)) -> 출시전 | CI12: =IF(AND(AM12=0,BK12=0),"출시전",IF(AND(AM12=0,BK12>0),"미출고",AM12/BK12)) -> 출시전 | CJ12: =IF(AND(AN12=0,BL12=0),"출시전",IF(AND(AN12=0,BL12>0),"미출고",AN12/BL12)) -> 출시전 | CK12: =IF(AND(AO12=0,BM12=0),"출시전",IF(AND(AO12=0,BM12>0),"미출고",AO12/BM12)) -> 출시전 | CL12: =IF(AND(AP12=0,BN12=0),"출시전",IF(AND(AP12=0,BN12>0),"미출고",AP12/BN12)) -> 0.0037709976 | ... CS12: =IF(AND(AW12=0,BU12=0),"출시전",IF(AND(AW12=0,BU12>0),"미출고",AW12/BU12)) -> 0.069755336
A13: 완제품 | B13: 314433 | C13: 베러미트 식물성 미트볼 | D13: 1 | E13: =IFERROR(VLOOKUP(B13,재고DB!H:AS,38,FALSE),0) -> 5609 | F13: =SUMIF(재고DB!$H:$H,완제품!$B13,재고DB!$AB:$AB) -> 738 | G13: =+E13*F13 -> 4139442 | H13: =IFERROR(VLOOKUP(B13,출고량!$A:$D,4,FALSE),0) -> 332.83871 | I13: =IFERROR(F13/H13,0) -> 2.2172902 | J13: =IF(F13=0,"재고없음",IF(H13=0,"출고없음",$H$1+I13*30)) -> 45869.519 | K13: =IF(F13=0,"재고없음",IFERROR(VLOOKUP(B13,재고DB!H:BU,66,FALSE),0)) -> 46117 | L13: 28 | M13: =+L13+$H$1 -> 45831 | N13: 0.95 | O13: =IFERROR(IF(M13-J13>0,"O","X"),"없음") -> X | P13: 0 | Q13: =+P13/D13*N13 -> 0 | R13: =IFERROR((Q13+F13)/H13*30+$H$1,"없음") -> 45869.519 | S13: =IFERROR(IF(J13="출고없음","X",IF(K13-J13>0,"O","X")),0) -> O | T13: =IF(J13="출고없음",$V$2,IF(I13=0,"-",IF(I13<=1,$S$2,IF(AND(I13>1,I13<=4),$T$2,$V$2)))) -> B | U13: =COUNTIF(CH13:CS13,"<0.1")+COUNTIF(CH13:CS13,"=미출고") -> 0 | V13: =IF(AND(S13="X",T13="C",U13>4),"단산검토",IF(AND(S13="X",T13="C"),"소진계획필요","판매활성화")) -> 판매활성화 | Z13: 1500 | AI13: 1022 | AJ13: 750 | AK13: 730 | AL13: 1512 | AM13: 605 | AN13: 764 | AO13: 462 | AP13: 498 | AQ13: 1349 | AR13: 422 | AS13: 201 | AT13: 155 | AU13: 198 | AV13: 184 | AW13: 327 | AX13: 879 | BG13: 1243 | BH13: 1835 | BI13: 1112 | BJ13: 2710 | BK13: 2070 | BL13: 1343 | BM13: 3650 | BN13: 3147 | BO13: 1824 | BP13: 1376 | BQ13: 1180 | BR13: 1025 | BS13: 793 | BT13: 600 | BU13: 313 | CE13: =IF(AND(AI13=0,BG13=0),"출시전",IF(AND(AI13=0,BG13>0),"미출고",AI13/BG13)) -> 0.82220434 | CF13: =IF(AND(AJ13=0,BH13=0),"출시전",IF(AND(AJ13=0,BH13>0),"미출고",AJ13/BH13)) -> 0.40871935 | CG13: =IF(AND(AK13=0,BI13=0),"출시전",IF(AND(AK13=0,BI13>0),"미출고",AK13/BI13)) -> 0.65647482 | CH13: =IF(AND(AL13=0,BJ13=0),"출시전",IF(AND(AL13=0,BJ13>0),"미출고",AL13/BJ13)) -> 0.55793358 | CI13: =IF(AND(AM13=0,BK13=0),"출시전",IF(AND(AM13=0,BK13>0),"미출고",AM13/BK13)) -> 0.29227053 | CJ13: =IF(AND(AN13=0,BL13=0),"출시전",IF(AND(AN13=0,BL13>0),"미출고",AN13/BL13)) -> 0.56887565 | CK13: =IF(AND(AO13=0,BM13=0),"출시전",IF(AND(AO13=0,BM13>0),"미출고",AO13/BM13)) -> 0.12657534 | CL13: =IF(AND(AP13=0,BN13=0),"출시전",IF(AND(AP13=0,BN13>0),"미출고",AP13/BN13)) -> 0.15824595 | ... CS13: =IF(AND(AW13=0,BU13=0),"출시전",IF(AND(AW13=0,BU13>0),"미출고",AW13/BU13)) -> 1.0447284
A14: 완제품 | B14: 317361 | C14: 베러미트 식물성 민스 | D14: 4 | E14: =IFERROR(VLOOKUP(B14,재고DB!H:AS,38,FALSE),0) -> 17230 | F14: =SUMIF(재고DB!$H:$H,완제품!$B14,재고DB!$AB:$AB) -> 157 | G14: =+E14*F14 -> 2705110 | H14: =IFERROR(VLOOKUP(B14,출고량!$A:$D,4,FALSE),0) -> 129.74194 | I14: =IFERROR(F14/H14,0) -> 1.2100945 | J14: =IF(F14=0,"재고없음",IF(H14=0,"출고없음",$H$1+I14*30)) -> 45839.303 | K14: =IF(F14=0,"재고없음",IFERROR(VLOOKUP(B14,재고DB!H:BU,66,FALSE),0)) -> 45997 | L14: 28 | M14: =+L14+$H$1 -> 45831 | N14: 0.95 | O14: =IFERROR(IF(M14-J14>0,"O","X"),"없음") -> X | P14: 0 | Q14: =+P14/D14*N14 -> 0 | R14: =IFERROR((Q14+F14)/H14*30+$H$1,"없음") -> 45839.303 | S14: =IFERROR(IF(J14="출고없음","X",IF(K14-J14>0,"O","X")),0) -> O | T14: =IF(J14="출고없음",$V$2,IF(I14=0,"-",IF(I14<=1,$S$2,IF(AND(I14>1,I14<=4),$T$2,$V$2)))) -> B | U14: =COUNTIF(CH14:CS14,"<0.1")+COUNTIF(CH14:CS14,"=미출고") -> 0 | V14: =IF(AND(S14="X",T14="C",U14>4),"단산검토",IF(AND(S14="X",T14="C"),"소진계획필요","판매활성화")) -> 판매활성화 | AI14: 63 | AJ14: 57 | AK14: 60 | AL14: 369 | AM14: 281 | AN14: 536 | AO14: 587 | AP14: 239 | AQ14: 394 | AR14: 161 | AS14: 403 | AT14: 116 | AU14: 127 | AV14: 138 | AW14: 123 | AX14: 216 | BG14: 363 | BH14: 306 | BI14: 619 | BJ14: 242 | BK14: 949 | BL14: 1178 | BM14: 1089 | BN14: 1355 | BO14: 957 | BP14: 791 | BQ14: 391 | BR14: 771 | BS14: 602 | BT14: 491 | BU14: 437 | CE14: =IF(AND(AI14=0,BG14=0),"출시전",IF(AND(AI14=0,BG14>0),"미출고",AI14/BG14)) -> 0.17355372 | CF14: =IF(AND(AJ14=0,BH14=0),"출시전",IF(AND(AJ14=0,BH14>0),"미출고",AJ14/BH14)) -> 0.18627451 | CG14: =IF(AND(AK14=0,BI14=0),"출시전",IF(AND(AK14=0,BI14>0),"미출고",AK14/BI14)) -> 0.096930533 | CH14: =IF(AND(AL14=0,BJ14=0),"출시전",IF(AND(AL14=0,BJ14>0),"미출고",AL14/BJ14)) -> 1.5247934 | CI14: =IF(AND(AM14=0,BK14=0),"출시전",IF(AND(AM14=0,BK14>0),"미출고",AM14/BK14)) -> 0.29610116 | CJ14: =IF(AND(AN14=0,BL14=0),"출시전",IF(AND(AN14=0,BL14>0),"미출고",AN14/BL14)) -> 0.45500849 | CK14: =IF(AND(AO14=0,BM14=0),"출시전",IF(AND(AO14=0,BM14>0),"미출고",AO14/BM14)) -> 0.53902663 | CL14: =IF(AND(AP14=0,BN14=0),"출시전",IF(AND(AP14=0,BN14>0),"미출고",AP14/BN14)) -> 0.17638376 | ... CS14: =IF(AND(AW14=0,BU14=0),"출시전",IF(AND(AW14=0,BU14>0),"미출고",AW14/BU14)) -> 0.28146453
A15: 완제품 | B15: 314432 | C15: 베러미트 식물성 소시지패티 (단산) | D15: 1.04 | E15: =IFERROR(VLOOKUP(B15,재고DB!H:AS,38,FALSE),0) -> 0 | F15: =SUMIF(재고DB!$H:$H,완제품!$B15,재고DB!$AB:$AB) -> 0 | G15: =+E15*F15 -> 0 | H15: =IFERROR(VLOOKUP(B15,출고량!$A:$D,4,FALSE),0) -> 38.870968 | I15: =IFERROR(F15/H15,0) -> 0 | J15: =IF(F15=0,"재고없음",IF(H15=0,"출고없음",$H$1+I15*30)) -> 재고없음 | K15: =IF(F15=0,"재고없음",IFERROR(VLOOKUP(B15,재고DB!H:BU,66,FALSE),0)) -> 재고없음 | L15: 28 | M15: =+L15+$H$1 -> 45831 | N15: 0.95 | O15: =IFERROR(IF(M15-J15>0,"O","X"),"없음") -> 없음 | P15: 0 | Q15: =+P15/D15*N15 -> 0 | R15: =IFERROR((Q15+F15)/H15*30+$H$1,"없음") -> 45803 | S15: =IFERROR(IF(J15="출고없음","X",IF(K15-J15>0,"O","X")),0) -> 0 | T15: =IF(J15="출고없음",$V$2,IF(I15=0,"-",IF(I15<=1,$S$2,IF(AND(I15>1,I15<=4),$T$2,$V$2)))) -> - | U15: =COUNTIF(CH15:CS15,"<0.1")+COUNTIF(CH15:CS15,"=미출고") -> 5 | V15: =IF(AND(S15="X",T15="C",U15>4),"단산검토",IF(AND(S15="X",T15="C"),"소진계획필요","판매활성화")) -> 판매활성화 | AI15: 38 | AJ15: 256 | AK15: 842 | AL15: 1283 | AM15: 963 | AN15: 591 | AO15: 97 | AP15: 53 | AQ15: 128 | AR15: 47 | AS15: 82 | AT15: 63 | AU15: 215 | AV15: 88 | AW15: 182 | AX15: 139 | BG15: 2069 | BH15: 1897 | BI15: 1055 | BJ15: 1487 | BK15: 2002 | BL15: 1463 | BM15: 1366 | BN15: 1313 | BO15: 1187 | BP15: 1138 | BQ15: 1056 | BR15: 993 | BS15: 776 | BT15: 690 | BU15: 508 | CE15: =IF(AND(AI15=0,BG15=0),"출시전",IF(AND(AI15=0,BG15>0),"미출고",AI15/BG15)) -> 0.018366361 | CF15: =IF(AND(AJ15=0,BH15=0),"출시전",IF(AND(AJ15=0,BH15>0),"미출고",AJ15/BH15)) -> 0.13494992 | CG15: =IF(AND(AK15=0,BI15=0),"출시전",IF(AND(AK15=0,BI15>0),"미출고",AK15/BI15)) -> 0.79810427 | CH15: =IF(AND(AL15=0,BJ15=0),"출시전",IF(AND(AL15=0,BJ15>0),"미출고",AL15/BJ15)) -> 0.86281103 | CI15: =IF(AND(AM15=0,BK15=0),"출시전",IF(AND(AM15=0,BK15>0),"미출고",AM15/BK15)) -> 0.48101898 | CJ15: =IF(AND(AN15=0,BL15=0),"출시전",IF(AND(AN15=0,BL15>0),"미출고",AN15/BL15)) -> 0.40396446 | CK15: =IF(AND(AO15=0,BM15=0),"출시전",IF(AND(AO15=0,BM15>0),"미출고",AO15/BM15)) -> 0.071010249 | CL15: =IF(AND(AP15=0,BN15=0),"출시전",IF(AND(AP15=0,BN15>0),"미출고",AP15/BN15)) -> 0.040365575 | ... CS15: =IF(AND(AW15=0,BU15=0),"출시전",IF(AND(AW15=0,BU15>0),"미출고",AW15/BU15)) -> 0.35826772
A16: 완제품 | B16: 321617 | C16: 베러미트 식물성 베러패티 | D16: 1.264 | E16: =IFERROR(VLOOKUP(B16,재고DB!H:AS,38,FALSE),0) -> 7209 | F16: =SUMIF(재고DB!$H:$H,완제품!$B16,재고DB!$AB:$AB) -> 447 | G16: =+E16*F16 -> 3222423 | H16: =IFERROR(VLOOKUP(B16,출고량!$A:$D,4,FALSE),0) -> 948.25806 | I16: =IFERROR(F16/H16,0) -> 0.47139067 | J16: =IF(F16=0,"재고없음",IF(H16=0,"출고없음",$H$1+I16*30)) -> 45817.142 | K16: =IF(F16=0,"재고없음",IFERROR(VLOOKUP(B16,재고DB!H:BU,66,FALSE),0)) -> 46097 | L16: 28 | M16: =+L16+$H$1 -> 45831 | N16: 0.8439 | O16: =IFERROR(IF(M16-J16>0,"O","X"),"없음") -> O | P16: 1500 | Q16: =+P16/D16*N16 -> 1001.4636 | R16: =IFERROR((Q16+F16)/H16*30+$H$1,"없음") -> 45848.825 | S16: =IFERROR(IF(J16="출고없음","X",IF(K16-J16>0,"O","X")),0) -> O | T16: =IF(J16="출고없음",$V$2,IF(I16=0,"-",IF(I16<=1,$S$2,IF(AND(I16>1,I16<=4),$T$2,$V$2)))) -> A | U16: =COUNTIF(CH16:CS16,"<0.1")+COUNTIF(CH16:CS16,"=미출고") -> 0 | V16: =IF(AND(S16="X",T16="C",U16>4),"단산검토",IF(AND(S16="X",T16="C"),"소진계획필요","판매활성화")) -> 판매활성화 | X16: 2000 | Y16: 2000 | AI16: 200 | AJ16: 492 | AK16: 901 | AL16: 1701 | AM16: 2268 | AN16: 1528 | AO16: 1394 | AP16: 1740 | AQ16: 1318 | AR16: 1604 | AS16: 1811 | AT16: 1194 | AU16: 1122 | AV16: 919 | AW16: 1134 | AX16: 838 | BG16: 808 | BH16: 2094 | BI16: 1228 | BJ16: 2412 | BK16: 2944 | BL16: 2582 | BM16: 2216 | BN16: 2702 | BO16: 1381 | BP16: 1058 | BQ16: 2166 | BR16: 1932 | BS16: 1016 | BT16: 1558 | BU16: 1982 | CE16: =IF(AND(AI16=0,BG16=0),"출시전",IF(AND(AI16=0,BG16>0),"미출고",AI16/BG16)) -> 0.24752475 | CF16: =IF(AND(AJ16=0,BH16=0),"출시전",IF(AND(AJ16=0,BH16>0),"미출고",AJ16/BH16)) -> 0.23495702 | CG16: =IF(AND(AK16=0,BI16=0),"출시전",IF(AND(AK16=0,BI16>0),"미출고",AK16/BI16)) -> 0.73371336 | CH16: =IF(AND(AL16=0,BJ16=0),"출시전",IF(AND(AL16=0,BJ16>0),"미출고",AL16/BJ16)) -> 0.70522388 | CI16: =IF(AND(AM16=0,BK16=0),"출시전",IF(AND(AM16=0,BK16>0),"미출고",AM16/BK16)) -> 0.77038043 | CJ16: =IF(AND(AN16=0,BL16=0),"출시전",IF(AND(AN16=0,BL16>0),"미출고",AN16/BL16)) -> 0.59178931 | CK16: =IF(AND(AO16=0,BM16=0),"출시전",IF(AND(AO16=0,BM16>0),"미출고",AO16/BM16)) -> 0.62906137 | CL16: =IF(AND(AP16=0,BN16=0),"출시전",IF(AND(AP16=0,BN16>0),"미출고",AP16/BN16)) -> 0.64396743 | ... CS16: =IF(AND(AW16=0,BU16=0),"출시전",IF(AND(AW16=0,BU16>0),"미출고",AW16/BU16)) -> 0.57214934
A17: 완제품 | B17: 334659 | C17: 유아왓유잇 식물성 허브 치킨스테이크 슈레드 | D17: 0.3 | E17: =IFERROR(VLOOKUP(B17,재고DB!H:AS,38,FALSE),0) -> 2657 | F17: =SUMIF(재고DB!$H:$H,완제품!$B17,재고DB!$AB:$AB) -> 675 | G17: =+E17*F17 -> 1793475 | H17: =IFERROR(VLOOKUP(B17,출고량!$A:$D,4,FALSE),0) -> 1.5483871 | I17: =IFERROR(F17/H17,0) -> 435.9375 | J17: =IF(F17=0,"재고없음",IF(H17=0,"출고없음",$H$1+I17*30)) -> 58881.125 | K17: =IF(F17=0,"재고없음",IFERROR(VLOOKUP(B17,재고DB!H:BU,66,FALSE),0)) -> 45934 | L17: 42 | M17: =+L17+$H$1 -> 45845 | N17: 0.9 | O17: =IFERROR(IF(M17-J17>0,"O","X"),"없음") -> X | P17: 0 | Q17: =+P17/D17*N17 -> 0 | R17: =IFERROR((Q17+F17)/H17*30+$H$1,"없음") -> 58881.125 | S17: =IFERROR(IF(J17="출고없음","X",IF(K17-J17>0,"O","X")),0) -> X | T17: =IF(J17="출고없음",$V$2,IF(I17=0,"-",IF(I17<=1,$S$2,IF(AND(I17>1,I17<=4),$T$2,$V$2)))) -> C | U17: =COUNTIF(CH17:CS17,"<0.1")+COUNTIF(CH17:CS17,"=미출고") -> 4 | V17: =IF(AND(S17="X",T17="C",U17>4),"단산검토",IF(AND(S17="X",T17="C"),"소진계획필요","판매활성화")) -> 소진계획필요 | AI17: 0 | AJ17: 0 | AK17: 0 | AL17: 0 | AM17: 0 | AN17: 0 | AO17: 0 | AP17: 0 | AQ17: 0 | AR17: 91 | AS17: 2 | AT17: 80 | AU17: 11 | AV17: 2 | AW17: 4 | AX17: 6 | BG17: 0 | BH17: 0 | BI17: 0 | BJ17: 0 | BK17: 0 | BL17: 0 | BM17: 0 | BN17: 0 | BO17: 0 | BP17: 798 | BQ17: 798 | BR17: 718 | BS17: 689 | BT17: 685 | BU17: 681 | CE17: =IF(AND(AI17=0,BG17=0),"출시전",IF(AND(AI17=0,BG17>0),"미출고",AI17/BG17)) -> 출시전 | CF17: =IF(AND(AJ17=0,BH17=0),"출시전",IF(AND(AJ17=0,BH17>0),"미출고",AJ17/BH17)) -> 출시전 | CG17: =IF(AND(AK17=0,BI17=0),"출시전",IF(AND(AK17=0,BI17>0),"미출고",AK17/BI17)) -> 출시전 | CH17: =IF(AND(AL17=0,BJ17=0),"출시전",IF(AND(AL17=0,BJ17>0),"미출고",AL17/BJ17)) -> 출시전 | CI17: =IF(AND(AM17=0,BK17=0),"출시전",IF(AND(AM17=0,BK17>0),"미출고",AM17/BK17)) -> 출시전 | CJ17: =IF(AND(AN17=0,BL17=0),"출시전",IF(AND(AN17=0,BL17>0),"미출고",AN17/BL17)) -> 출시전 | CK17: =IF(AND(AO17=0,BM17=0),"출시전",IF(AND(AO17=0,BM17>0),"미출고",AO17/BM17)) -> 출시전 | CL17: =IF(AND(AP17=0,BN17=0),"출시전",IF(AND(AP17=0,BN17>0),"미출고",AP17/BN17)) -> 출시전 | ... CS17: =IF(AND(AW17=0,BU17=0),"출시전",IF(AND(AW17=0,BU17>0),"미출고",AW17/BU17)) -> 0.0058737151
A18: 완제품 | B18: 320471 | C18: 베러미트 식물성 프리미엄 런천 슬라이스 | D18: 1.08 | E18: =IFERROR(VLOOKUP(B18,재고DB!H:AS,38,FALSE),0) -> 7776 | F18: =SUMIF(재고DB!$H:$H,완제품!$B18,재고DB!$AB:$AB) -> 248 | G18: =+E18*F18 -> 1928448 | H18: =IFERROR(VLOOKUP(B18,출고량!$A:$D,4,FALSE),0) -> 721.19355 | I18: =IFERROR(F18/H18,0) -> 0.3438744 | J18: =IF(F18=0,"재고없음",IF(H18=0,"출고없음",$H$1+I18*30)) -> 45813.316 | K18: =IF(F18=0,"재고없음",IFERROR(VLOOKUP(B18,재고DB!H:BU,66,FALSE),0)) -> 46019 | L18: 28 | M18: =+L18+$H$1 -> 45831 | N18: 0.88 | O18: =IFERROR(IF(M18-J18>0,"O","X"),"없음") -> O | P18: 1500 | Q18: =+P18/D18*N18 -> 1222.2222 | R18: =IFERROR((Q18+F18)/H18*30+$H$1,"없음") -> 45864.158 | S18: =IFERROR(IF(J18="출고없음","X",IF(K18-J18>0,"O","X")),0) -> O | T18: =IF(J18="출고없음",$V$2,IF(I18=0,"-",IF(I18<=1,$S$2,IF(AND(I18>1,I18<=4),$T$2,$V$2)))) -> A | U18: =COUNTIF(CH18:CS18,"<0.1")+COUNTIF(CH18:CS18,"=미출고") -> 0 | V18: =IF(AND(S18="X",T18="C",U18>4),"단산검토",IF(AND(S18="X",T18="C"),"소진계획필요","판매활성화")) -> 판매활성화 | AA18: 1500 | AI18: 0 | AJ18: 0 | AK18: 1873 | AL18: 3955 | AM18: 3122 | AN18: 2242 | AO18: 1990 | AP18: 784 | AQ18: 927 | AR18: 673 | AS18: 610 | AT18: 1372 | AU18: 244 | AV18: 240 | AW18: 571 | AX18: 892 | BG18: 0 | BH18: 1261 | BI18: 1105 | BJ18: 5545 | BK18: 5897 | BL18: 3896 | BM18: 3182 | BN18: 2420 | BO18: 1483 | BP18: 794 | BQ18: 2361 | BR18: 989 | BS18: 2310 | BT18: 2188 | BU18: 1593 | CE18: =IF(AND(AI18=0,BG18=0),"출시전",IF(AND(AI18=0,BG18>0),"미출고",AI18/BG18)) -> 출시전 | CF18: =IF(AND(AJ18=0,BH18=0),"출시전",IF(AND(AJ18=0,BH18>0),"미출고",AJ18/BH18)) -> 미출고 | CG18: =IF(AND(AK18=0,BI18=0),"출시전",IF(AND(AK18=0,BI18>0),"미출고",AK18/BI18)) -> 1.6950226 | CH18: =IF(AND(AL18=0,BJ18=0),"출시전",IF(AND(AL18=0,BJ18>0),"미출고",AL18/BJ18)) -> 0.71325518 | CI18: =IF(AND(AM18=0,BK18=0),"출시전",IF(AND(AM18=0,BK18>0),"미출고",AM18/BK18)) -> 0.52942174 | CJ18: =IF(AND(AN18=0,BL18=0),"출시전",IF(AND(AN18=0,BL18>0),"미출고",AN18/BL18)) -> 0.57546201 | CK18: =IF(AND(AO18=0,BM18=0),"출시전",IF(AND(AO18=0,BM18>0),"미출고",AO18/BM18)) -> 0.62539283 | CL18: =IF(AND(AP18=0,BN18=0),"출시전",IF(AND(AP18=0,BN18>0),"미출고",AP18/BN18)) -> 0.32396694 | ... CS18: =IF(AND(AW18=0,BU18=0),"출시전",IF(AND(AW18=0,BU18>0),"미출고",AW18/BU18)) -> 0.35844319
A19: 완제품 | B19: 321310 | C19: 식물성 런천 200G (SPC) | D19: 0.2 | E19: =IFERROR(VLOOKUP(B19,재고DB!H:AS,38,FALSE),0) -> 2180 | F19: =SUMIF(재고DB!$H:$H,완제품!$B19,재고DB!$AB:$AB) -> 11983 | G19: =+E19*F19 -> 26122940 | H19: =IFERROR(VLOOKUP(B19,출고량!$A:$D,4,FALSE),0) -> 227.87097 | I19: =IFERROR(F19/H19,0) -> 52.586778 | J19: =IF(F19=0,"재고없음",IF(H19=0,"출고없음",$H$1+I19*30)) -> 47380.603 | K19: =IF(F19=0,"재고없음",IFERROR(VLOOKUP(B19,재고DB!H:BU,66,FALSE),0)) -> 46239 | L19: 42 | M19: =+L19+$H$1 -> 45845 | N19: 0.98 | O19: =IFERROR(IF(M19-J19>0,"O","X"),"없음") -> X | P19: 0 | Q19: =+P19/D19*N19 -> 0 | R19: =IFERROR((Q19+F19)/H19*30+$H$1,"없음") -> 47380.603 | S19: =IFERROR(IF(J19="출고없음","X",IF(K19-J19>0,"O","X")),0) -> X | T19: =IF(J19="출고없음",$V$2,IF(I19=0,"-",IF(I19<=1,$S$2,IF(AND(I19>1,I19<=4),$T$2,$V$2)))) -> C | U19: =COUNTIF(CH19:CS19,"<0.1")+COUNTIF(CH19:CS19,"=미출고") -> 7 | V19: =IF(AND(S19="X",T19="C",U19>4),"단산검토",IF(AND(S19="X",T19="C"),"소진계획필요","판매활성화")) -> 단산검토 | AI19: 3608 | AJ19: 24 | AK19: 744 | AL19: 3242 | AM19: 1426 | AN19: 962 | AO19: 745 | AP19: 913 | AQ19: 1417 | AR19: 651 | AS19: 817 | AT19: 360 | AU19: 423 | AV19: 3178 | AW19: 552 | AX19: 480 | BG19: 3816 | BH19: 15672 | BI19: 14928 | BJ19: 9351 | BK19: 8247 | BL19: 7623 | BM19: 6927 | BN19: 18151 | BO19: 16759 | BP19: 16183 | BQ19: 15439 | BR19: 15079 | BS19: 14695 | BT19: 13015 | BU19: 12559 | CE19: =IF(AND(AI19=0,BG19=0),"출시전",IF(AND(AI19=0,BG19>0),"미출고",AI19/BG19)) -> 0.94549266 | CF19: =IF(AND(AJ19=0,BH19=0),"출시전",IF(AND(AJ19=0,BH19>0),"미출고",AJ19/BH19)) -> 0.0015313936 | CG19: =IF(AND(AK19=0,BI19=0),"출시전",IF(AND(AK19=0,BI19>0),"미출고",AK19/BI19)) -> 0.049839228 | CH19: =IF(AND(AL19=0,BJ19=0),"출시전",IF(AND(AL19=0,BJ19>0),"미출고",AL19/BJ19)) -> 0.34670089 | CI19: =IF(AND(AM19=0,BK19=0),"출시전",IF(AND(AM19=0,BK19>0),"미출고",AM19/BK19)) -> 0.17291136 | CJ19: =IF(AND(AN19=0,BL19=0),"출시전",IF(AND(AN19=0,BL19>0),"미출고",AN19/BL19)) -> 0.12619704 | CK19: =IF(AND(AO19=0,BM19=0),"출시전",IF(AND(AO19=0,BM19>0),"미출고",AO19/BM19)) -> 0.10755017 | CL19: =IF(AND(AP19=0,BN19=0),"출시전",IF(AND(AP19=0,BN19>0),"미출고",AP19/BN19)) -> 0.050300259 | ... CS19: =IF(AND(AW19=0,BU19=0),"출시전",IF(AND(AW19=0,BU19>0),"미출고",AW19/BU19)) -> 0.043952544
A20: 완제품 | B20: 323073 | C20: 식물성 런천 600G SPC 3입 | D20: 0.2 | E20: =IFERROR(VLOOKUP(B20,재고DB!H:AS,38,FALSE),0) -> 7100 | F20: =SUMIF(재고DB!$H:$H,완제품!$B20,재고DB!$AB:$AB) -> 3795 | G20: =+E20*F20 -> 26944500 | H20: =IFERROR(VLOOKUP(B20,출고량!$A:$D,4,FALSE),0) -> 13.870968 | I20: =IFERROR(F20/H20,0) -> 273.59302 | J20: =IF(F20=0,"재고없음",IF(H20=0,"출고없음",$H$1+I20*30)) -> 54010.791 | K20: =IF(F20=0,"재고없음",IFERROR(VLOOKUP(B20,재고DB!H:BU,66,FALSE),0)) -> 46078 | L20: 42 | M20: =+L20+$H$1 -> 45845 | N20: 0.98 | O20: =IFERROR(IF(M20-J20>0,"O","X"),"없음") -> X | P20: 0 | Q20: =+P20/D20*N20 -> 0 | R20: =IFERROR((Q20+F20)/H20*30+$H$1,"없음") -> 54010.791 | S20: =IFERROR(IF(J20="출고없음","X",IF(K20-J20>0,"O","X")),0) -> X | T20: =IF(J20="출고없음",$V$2,IF(I20=0,"-",IF(I20<=1,$S$2,IF(AND(I20>1,I20<=4),$T$2,$V$2)))) -> C | U20: =COUNTIF(CH20:CS20,"<0.1")+COUNTIF(CH20:CS20,"=미출고") -> 10 | V20: =IF(AND(S20="X",T20="C",U20>4),"단산검토",IF(AND(S20="X",T20="C"),"소진계획필요","판매활성화")) -> 단산검토 | AI20: 0 | AJ20: 0 | AK20: 349 | AL20: 811 | AM20: 587 | AN20: 372 | AO20: 202 | AP20: 209 | AQ20: 54 | AR20: 52 | AS20: 11 | AT20: 69 | AU20: 15 | AV20: 49 | AW20: 82 | AX20: 15 | BG20: 0 | BH20: 0 | BI20: 6208 | BJ20: 5140 | BK20: 4688 | BL20: 4397 | BM20: 4210 | BN20: 4067 | BO20: 4022 | BP20: 3977 | BQ20: 3975 | BR20: 3931 | BS20: 3881 | BT20: 3878 | BU20: 3802 | CE20: =IF(AND(AI20=0,BG20=0),"출시전",IF(AND(AI20=0,BG20>0),"미출고",AI20/BG20)) -> 출시전 | CF20: =IF(AND(AJ20=0,BH20=0),"출시전",IF(AND(AJ20=0,BH20>0),"미출고",AJ20/BH20)) -> 출시전 | CG20: =IF(AND(AK20=0,BI20=0),"출시전",IF(AND(AK20=0,BI20>0),"미출고",AK20/BI20)) -> 0.056217784 | CH20: =IF(AND(AL20=0,BJ20=0),"출시전",IF(AND(AL20=0,BJ20>0),"미출고",AL20/BJ20)) -> 0.1577821 | CI20: =IF(AND(AM20=0,BK20=0),"출시전",IF(AND(AM20=0,BK20>0),"미출고",AM20/BK20)) -> 0.12521331 | CJ20: =IF(AND(AN20=0,BL20=0),"출시전",IF(AND(AN20=0,BL20>0),"미출고",AN20/BL20)) -> 0.084603139 | CK20: =IF(AND(AO20=0,BM20=0),"출시전",IF(AND(AO20=0,BM20>0),"미출고",AO20/BM20)) -> 0.047980998 | CL20: =IF(AND(AP20=0,BN20=0),"출시전",IF(AND(AP20=0,BN20>0),"미출고",AP20/BN20)) -> 0.05138923 | ... CS20: =IF(AND(AW20=0,BU20=0),"출시전",IF(AND(AW20=0,BU20>0),"미출고",AW20/BU20)) -> 0.021567596
A21: 완제품 | B21: 323769 | C21: 베러미트 식물성 불고기 민스 | D21: 1 | E21: =IFERROR(VLOOKUP(B21,재고DB!H:AS,38,FALSE),0) -> 8300 | F21: =SUMIF(재고DB!$H:$H,완제품!$B21,재고DB!$AB:$AB) -> 2027 | G21: =+E21*F21 -> 16824100 | H21: =IFERROR(VLOOKUP(B21,출고량!$A:$D,4,FALSE),0) -> 3.7741935 | I21: =IFERROR(F21/H21,0) -> 537.06838 | J21: =IF(F21=0,"재고없음",IF(H21=0,"출고없음",$H$1+I21*30)) -> 61915.051 | K21: =IF(F21=0,"재고없음",IFERROR(VLOOKUP(B21,재고DB!H:BU,66,FALSE),0)) -> 45911 | L21: 35 | M21: =+L21+$H$1 -> 45838 | N21: 0.95 | O21: =IFERROR(IF(M21-J21>0,"O","X"),"없음") -> X | P21: 0 | Q21: =+P21/D21*N21 -> 0 | R21: =IFERROR((Q21+F21)/H21*30+$H$1,"없음") -> 61915.051 | S21: =IFERROR(IF(J21="출고없음","X",IF(K21-J21>0,"O","X")),0) -> X | T21: =IF(J21="출고없음",$V$2,IF(I21=0,"-",IF(I21<=1,$S$2,IF(AND(I21>1,I21<=4),$T$2,$V$2)))) -> C | U21: =COUNTIF(CH21:CS21,"<0.1")+COUNTIF(CH21:CS21,"=미출고") -> 11 | V21: =IF(AND(S21="X",T21="C",U21>4),"단산검토",IF(AND(S21="X",T21="C"),"소진계획필요","판매활성화")) -> 단산검토 | AI21: 0 | AJ21: 0 | AK21: 293 | AL21: 156 | AM21: 21 | AN21: 39 | AO21: 368 | AP21: 56 | AQ21: 9 | AR21: 4 | AS21: 10 | AT21: 5 | AU21: 6 | AV21: 19 | AW21: 25 | AX21: 3 | BG21: 0 | BH21: 0 | BI21: 2752 | BJ21: 2596 | BK21: 2575 | BL21: 2537 | BM21: 2168 | BN21: 2112 | BO21: 2103 | BP21: 2099 | BQ21: 2089 | BR21: 2084 | BS21: 2078 | BT21: 2058 | BU21: 2033 | CE21: =IF(AND(AI21=0,BG21=0),"출시전",IF(AND(AI21=0,BG21>0),"미출고",AI21/BG21)) -> 출시전 | CF21: =IF(AND(AJ21=0,BH21=0),"출시전",IF(AND(AJ21=0,BH21>0),"미출고",AJ21/BH21)) -> 출시전 | CG21: =IF(AND(AK21=0,BI21=0),"출시전",IF(AND(AK21=0,BI21>0),"미출고",AK21/BI21)) -> 0.10646802 | CH21: =IF(AND(AL21=0,BJ21=0),"출시전",IF(AND(AL21=0,BJ21>0),"미출고",AL21/BJ21)) -> 0.06009245 | CI21: =IF(AND(AM21=0,BK21=0),"출시전",IF(AND(AM21=0,BK21>0),"미출고",AM21/BK21)) -> 0.0081553398 | CJ21: =IF(AND(AN21=0,BL21=0),"출시전",IF(AND(AN21=0,BL21>0),"미출고",AN21/BL21)) -> 0.015372487 | CK21: =IF(AND(AO21=0,BM21=0),"출시전",IF(AND(AO21=0,BM21>0),"미출고",AO21/BM21)) -> 0.1697417 | CL21: =IF(AND(AP21=0,BN21=0),"출시전",IF(AND(AP21=0,BN21>0),"미출고",AP21/BN21)) -> 0.026515152 | ... CS21: =IF(AND(AW21=0,BU21=0),"출시전",IF(AND(AW21=0,BU21>0),"미출고",AW21/BU21)) -> 0.012297098
A22: 완제품 | B22: 326552 | C22: 베러미트 유아왓유잇 식물성 숯불직화 갈비구이 | D22: 1 | E22: =IFERROR(VLOOKUP(B22,재고DB!H:AS,38,FALSE),0) -> 0 | F22: =SUMIF(재고DB!$H:$H,완제품!$B22,재고DB!$AB:$AB) -> 0 | G22: =+E22*F22 -> 0 | H22: =IFERROR(VLOOKUP(B22,출고량!$A:$D,4,FALSE),0) -> 0 | I22: =IFERROR(F22/H22,0) -> 0 | J22: =IF(F22=0,"재고없음",IF(H22=0,"출고없음",$H$1+I22*30)) -> 재고없음 | K22: =IF(F22=0,"재고없음",IFERROR(VLOOKUP(B22,재고DB!H:BU,66,FALSE),0)) -> 재고없음 | L22: 0 | M22: =+L22+$H$1 -> 45803 | N22: 0.95 | O22: =IFERROR(IF(M22-J22>0,"O","X"),"없음") -> 없음 | P22: 0 | Q22: =+P22/D22*N22 -> 0 | R22: =IFERROR((Q22+F22)/H22*30+$H$1,"없음") -> 없음 | S22: =IFERROR(IF(J22="출고없음","X",IF(K22-J22>0,"O","X")),0) -> 0 | T22: =IF(J22="출고없음",$V$2,IF(I22=0,"-",IF(I22<=1,$S$2,IF(AND(I22>1,I22<=4),$T$2,$V$2)))) -> - | U22: =COUNTIF(CH22:CS22,"<0.1")+COUNTIF(CH22:CS22,"=미출고") -> 4 | V22: =IF(AND(S22="X",T22="C",U22>4),"단산검토",IF(AND(S22="X",T22="C"),"소진계획필요","판매활성화")) -> 판매활성화 | AI22: 0 | AJ22: 0 | AK22: 0 | AL22: 0 | AM22: 0 | AN22: 22 | AO22: 10 | AP22: 0 | AQ22: 0 | AR22: 0 | AS22: 0 | AT22: 0 | AU22: 0 | AV22: 0 | AW22: 0 | AX22: 0 | BG22: 0 | BH22: 0 | BI22: 0 | BJ22: 0 | BK22: 0 | BL22: 538 | BM22: 528 | BN22: 528 | BO22: 528 | BR22: 0 | BS22: 0 | BT22: 0 | BU22: 0 | CE22: =IF(AND(AI22=0,BG22=0),"출시전",IF(AND(AI22=0,BG22>0),"미출고",AI22/BG22)) -> 출시전 | CF22: =IF(AND(AJ22=0,BH22=0),"출시전",IF(AND(AJ22=0,BH22>0),"미출고",AJ22/BH22)) -> 출시전 | CG22: =IF(AND(AK22=0,BI22=0),"출시전",IF(AND(AK22=0,BI22>0),"미출고",AK22/BI22)) -> 출시전 | CH22: =IF(AND(AL22=0,BJ22=0),"출시전",IF(AND(AL22=0,BJ22>0),"미출고",AL22/BJ22)) -> 출시전 | CI22: =IF(AND(AM22=0,BK22=0),"출시전",IF(AND(AM22=0,BK22>0),"미출고",AM22/BK22)) -> 출시전 | CJ22: =IF(AND(AN22=0,BL22=0),"출시전",IF(AND(AN22=0,BL22>0),"미출고",AN22/BL22)) -> 0.040892193 | CK22: =IF(AND(AO22=0,BM22=0),"출시전",IF(AND(AO22=0,BM22>0),"미출고",AO22/BM22)) -> 0.018939394 | CL22: =IF(AND(AP22=0,BN22=0),"출시전",IF(AND(AP22=0,BN22>0),"미출고",AP22/BN22)) -> 미출고 | ... CS22: =IF(AND(AW22=0,BU22=0),"출시전",IF(AND(AW22=0,BU22>0),"미출고",AW22/BU22)) -> 출시전
A23: 완제품 | B23: 316950 | C23: 유아왓유잇 식물성 순대 (리뉴얼?) | D23: 1 | E23: =IFERROR(VLOOKUP(B23,재고DB!H:AS,38,FALSE),0) -> 0 | F23: =SUMIF(재고DB!$H:$H,완제품!$B23,재고DB!$AB:$AB) -> 0 | G23: =+E23*F23 -> 0 | H23: =IFERROR(VLOOKUP(B23,출고량!$A:$D,4,FALSE),0) -> 30.709677 | I23: =IFERROR(F23/H23,0) -> 0 | J23: =IF(F23=0,"재고없음",IF(H23=0,"출고없음",$H$1+I23*30)) -> 재고없음 | K23: =IF(F23=0,"재고없음",IFERROR(VLOOKUP(B23,재고DB!H:BU,66,FALSE),0)) -> 재고없음 | L23: 35 | M23: =+L23+$H$1 -> 45838 | N23: 0.95 | O23: =IFERROR(IF(M23-J23>0,"O","X"),"없음") -> 없음 | P23: 0 | Q23: =+P23/D23*N23 -> 0 | R23: =IFERROR((Q23+F23)/H23*30+$H$1,"없음") -> 45803 | S23: =IFERROR(IF(J23="출고없음","X",IF(K23-J23>0,"O","X")),0) -> 0 | T23: =IF(J23="출고없음",$V$2,IF(I23=0,"-",IF(I23<=1,$S$2,IF(AND(I23>1,I23<=4),$T$2,$V$2)))) -> - | U23: =COUNTIF(CH23:CS23,"<0.1")+COUNTIF(CH23:CS23,"=미출고") -> 8 | V23: =IF(AND(S23="X",T23="C",U23>4),"단산검토",IF(AND(S23="X",T23="C"),"소진계획필요","판매활성화")) -> 판매활성화 | AI23: 7 | AJ23: 259 | AK23: 88 | AL23: 100 | AM23: 58 | AN23: 8 | AO23: 230 | AP23: 23 | AQ23: 127 | AR23: 2 | AS23: 2 | AT23: 265 | AU23: 10 | AV23: 7 | AW23: 7 | AX23: 119 | BG23: 447 | BH23: 188 | BI23: 100 | BJ23: 100 | BK23: 792 | BL23: 784 | BM23: 559 | BN23: 547 | BO23: 404 | BP23: 401 | BQ23: 399 | BR23: 134 | BS23: 121 | BT23: 117 | BU23: 110 | CE23: =IF(AND(AI23=0,BG23=0),"출시전",IF(AND(AI23=0,BG23>0),"미출고",AI23/BG23)) -> 0.015659955 | CF23: =IF(AND(AJ23=0,BH23=0),"출시전",IF(AND(AJ23=0,BH23>0),"미출고",AJ23/BH23)) -> 1.3776596 | CG23: =IF(AND(AK23=0,BI23=0),"출시전",IF(AND(AK23=0,BI23>0),"미출고",AK23/BI23)) -> 0.88 | CH23: =IF(AND(AL23=0,BJ23=0),"출시전",IF(AND(AL23=0,BJ23>0),"미출고",AL23/BJ23)) -> 1 | CI23: =IF(AND(AM23=0,BK23=0),"출시전",IF(AND(AM23=0,BK23>0),"미출고",AM23/BK23)) -> 0.073232323 | CJ23: =IF(AND(AN23=0,BL23=0),"출시전",IF(AND(AN23=0,BL23>0),"미출고",AN23/BL23)) -> 0.010204082 | CK23: =IF(AND(AO23=0,BM23=0),"출시전",IF(AND(AO23=0,BM23>0),"미출고",AO23/BM23)) -> 0.41144902 | CL23: =IF(AND(AP23=0,BN23=0),"출시전",IF(AND(AP23=0,BN23>0),"미출고",AP23/BN23)) -> 0.042047532 | ... CS23: =IF(AND(AW23=0,BU23=0),"출시전",IF(AND(AW23=0,BU23>0),"미출고",AW23/BU23)) -> 0.063636364
A24: 완제품 | B24: 316953 | C24: 유아왓유잇 식물성 순대 (단산) | D24: 0.2 | E24: =IFERROR(VLOOKUP(B24,재고DB!H:AS,38,FALSE),0) -> 0 | F24: =SUMIF(재고DB!$H:$H,완제품!$B24,재고DB!$AB:$AB) -> 0 | G24: =+E24*F24 -> 0 | H24: =IFERROR(VLOOKUP(B24,출고량!$A:$D,4,FALSE),0) -> 2.5806452 | I24: =IFERROR(F24/H24,0) -> 0 | J24: =IF(F24=0,"재고없음",IF(H24=0,"출고없음",$H$1+I24*30)) -> 재고없음 | K24: =IF(F24=0,"재고없음",IFERROR(VLOOKUP(B24,재고DB!H:BU,66,FALSE),0)) -> 재고없음 | L24: 35 | M24: =+L24+$H$1 -> 45838 | N24: 0.95 | O24: =IFERROR(IF(M24-J24>0,"O","X"),"없음") -> 없음 | P24: 0 | Q24: =+P24/D24*N24 -> 0 | R24: =IFERROR((Q24+F24)/H24*30+$H$1,"없음") -> 45803 | S24: =IFERROR(IF(J24="출고없음","X",IF(K24-J24>0,"O","X")),0) -> 0 | T24: =IF(J24="출고없음",$V$2,IF(I24=0,"-",IF(I24<=1,$S$2,IF(AND(I24>1,I24<=4),$T$2,$V$2)))) -> - | U24: =COUNTIF(CH24:CS24,"<0.1")+COUNTIF(CH24:CS24,"=미출고") -> 11 | V24: =IF(AND(S24="X",T24="C",U24>4),"단산검토",IF(AND(S24="X",T24="C"),"소진계획필요","판매활성화")) -> 판매활성화 | AI24: 0 | AJ24: 1061 | AK24: 0 | AL24: 2608 | AM24: 5 | AN24: 1 | AO24: 5 | AP24: 25 | AQ24: 0 | AR24: 3 | AS24: 0 | AT24: 6 | AU24: 5 | AV24: 0 | AW24: 4 | AX24: 10 | BG24: 0 | BH24: 1061 | BI24: 0 | BJ24: 1200 | BK24: 1195 | BL24: 1194 | BM24: 1194 | BN24: 1164 | BO24: 1164 | BP24: 1161 | BQ24: 1161 | BR24: 1155 | BS24: 1150 | BT24: 1150 | BU24: 1146 | CE24: =IF(AND(AI24=0,BG24=0),"출시전",IF(AND(AI24=0,BG24>0),"미출고",AI24/BG24)) -> 출시전 | CF24: =IF(AND(AJ24=0,BH24=0),"출시전",IF(AND(AJ24=0,BH24>0),"미출고",AJ24/BH24)) -> 1 | CG24: =IF(AND(AK24=0,BI24=0),"출시전",IF(AND(AK24=0,BI24>0),"미출고",AK24/BI24)) -> 출시전 | CH24: =IF(AND(AL24=0,BJ24=0),"출시전",IF(AND(AL24=0,BJ24>0),"미출고",AL24/BJ24)) -> 2.1733333 | CI24: =IF(AND(AM24=0,BK24=0),"출시전",IF(AND(AM24=0,BK24>0),"미출고",AM24/BK24)) -> 0.0041841004 | CJ24: =IF(AND(AN24=0,BL24=0),"출시전",IF(AND(AN24=0,BL24>0),"미출고",AN24/BL24)) -> 0.00083752094 | CK24: =IF(AND(AO24=0,BM24=0),"출시전",IF(AND(AO24=0,BM24>0),"미출고",AO24/BM24)) -> 0.0041876047 | CL24: =IF(AND(AP24=0,BN24=0),"출시전",IF(AND(AP24=0,BN24>0),"미출고",AP24/BN24)) -> 0.021477663 | ... CS24: =IF(AND(AW24=0,BU24=0),"출시전",IF(AND(AW24=0,BU24>0),"미출고",AW24/BU24)) -> 0.0034904014
A25: 완제품 | B25: 321093 | C25: YWE 식물성 체다향 치즈 슬라이스 (단산) | D25: 0.17 | E25: =IFERROR(VLOOKUP(B25,재고DB!H:AS,38,FALSE),0) -> 0 | F25: =SUMIF(재고DB!$H:$H,완제품!$B25,재고DB!$AB:$AB) -> 0 | G25: =+E25*F25 -> 0 | H25: =IFERROR(VLOOKUP(B25,출고량!$A:$D,4,FALSE),0) -> 9.2903226 | I25: =IFERROR(F25/H25,0) -> 0 | J25: =IF(F25=0,"재고없음",IF(H25=0,"출고없음",$H$1+I25*30)) -> 재고없음 | K25: =IF(F25=0,"재고없음",IFERROR(VLOOKUP(B25,재고DB!H:BU,66,FALSE),0)) -> 재고없음 | L25: 35 | M25: =+L25+$H$1 -> 45838 | N25: 1 | O25: =IFERROR(IF(M25-J25>0,"O","X"),"없음") -> 없음 | Q25: =+P25/D25*N25 -> 0 | R25: =IFERROR((Q25+F25)/H25*30+$H$1,"없음") -> 45803 | S25: =IFERROR(IF(J25="출고없음","X",IF(K25-J25>0,"O","X")),0) -> 0 | T25: =IF(J25="출고없음",$V$2,IF(I25=0,"-",IF(I25<=1,$S$2,IF(AND(I25>1,I25<=4),$T$2,$V$2)))) -> - | U25: =COUNTIF(CH25:CS25,"<0.1")+COUNTIF(CH25:CS25,"=미출고") -> 1 | V25: =IF(AND(S25="X",T25="C",U25>4),"단산검토",IF(AND(S25="X",T25="C"),"소진계획필요","판매활성화")) -> 판매활성화 | AI25: 0 | AJ25: 0 | AK25: 0 | AL25: 0 | AM25: 0 | AN25: 843 | AO25: 958 | AP25: 8185 | AQ25: 2066 | AR25: 2984 | AS25: 2554 | AT25: 1464 | AU25: 1216 | AV25: 1571 | AW25: 816 | AX25: 36 | BG25: 0 | BH25: 0 | BI25: 0 | BJ25: 0 | BK25: 0 | BL25: 4656 | BM25: 12376 | BN25: 4347 | BO25: 2234 | BP25: 7472 | BQ25: 5041 | BR25: 3355 | BS25: 1686 | BT25: 495 | BU25: =+BT25 -> 495 | CE25: =IF(AND(AI25=0,BG25=0),"출시전",IF(AND(AI25=0,BG25>0),"미출고",AI25/BG25)) -> 출시전 | CF25: =IF(AND(AJ25=0,BH25=0),"출시전",IF(AND(AJ25=0,BH25>0),"미출고",AJ25/BH25)) -> 출시전 | CG25: =IF(AND(AK25=0,BI25=0),"출시전",IF(AND(AK25=0,BI25>0),"미출고",AK25/BI25)) -> 출시전 | CH25: =IF(AND(AL25=0,BJ25=0),"출시전",IF(AND(AL25=0,BJ25>0),"미출고",AL25/BJ25)) -> 출시전 | CI25: =IF(AND(AM25=0,BK25=0),"출시전",IF(AND(AM25=0,BK25>0),"미출고",AM25/BK25)) -> 출시전 | CJ25: =IF(AND(AN25=0,BL25=0),"출시전",IF(AND(AN25=0,BL25>0),"미출고",AN25/BL25)) -> 0.1810567 | CK25: =IF(AND(AO25=0,BM25=0),"출시전",IF(AND(AO25=0,BM25>0),"미출고",AO25/BM25)) -> 0.077407886 | CL25: =IF(AND(AP25=0,BN25=0),"출시전",IF(AND(AP25=0,BN25>0),"미출고",AP25/BN25)) -> 1.8829078 | ... CS25: =IF(AND(AW25=0,BU25=0),"출시전",IF(AND(AW25=0,BU25>0),"미출고",AW25/BU25)) -> 1.6484848
A26: 완제품 | B26: 331934 | C26: YWE 식물성 오트 휘핑크림 서강유업 1L | D26: 1 | E26: =IFERROR(VLOOKUP(B26,재고DB!H:AS,38,FALSE),0) -> 2900 | F26: =SUMIF(재고DB!$H:$H,완제품!$B26,재고DB!$AB:$AB) -> 9208 | G26: =+E26*F26 -> 26703200 | H26: =IFERROR(VLOOKUP(B26,출고량!$A:$D,4,FALSE),0) -> 4614.0968 | I26: =IFERROR(F26/H26,0) -> 1.9956235 | J26: =IF(F26=0,"재고없음",IF(H26=0,"출고없음",$H$1+I26*30)) -> 45862.869 | K26: =IF(F26=0,"재고없음",IFERROR(VLOOKUP(B26,재고DB!H:BU,66,FALSE),0)) -> 45875 | L26: =14+7 -> 21 | M26: =+L26+$H$1 -> 45824 | N26: 0.9 | O26: =IFERROR(IF(M26-J26>0,"O","X"),"없음") -> X | Q26: =+P26/D26*N26 -> 0 | R26: =IFERROR((Q26+F26)/H26*30+$H$1,"없음") -> 45862.869 | S26: =IFERROR(IF(J26="출고없음","X",IF(K26-J26>0,"O","X")),0) -> O | T26: =IF(J26="출고없음",$V$2,IF(I26=0,"-",IF(I26<=1,$S$2,IF(AND(I26>1,I26<=4),$T$2,$V$2)))) -> B | U26: =COUNTIF(CH26:CS26,"<0.1")+COUNTIF(CH26:CS26,"=미출고") -> 0 | V26: =IF(AND(S26="X",T26="C",U26>4),"단산검토",IF(AND(S26="X",T26="C"),"소진계획필요","판매활성화")) -> 판매활성화 | W26: 15000 | X26: 20000 | AI26: 0 | AJ26: 0 | AK26: 0 | AL26: 0 | AM26: 0 | AN26: 2161 | AO26: 2316 | AP26: 2529 | AQ26: 4810 | AR26: 3940 | AS26: 1620 | AT26: 5037 | AU26: 9046 | AV26: 4059 | AW26: 6010 | AX26: 3670 | BG26: 0 | BH26: 0 | BI26: 0 | BJ26: 0 | BK26: 0 | BL26: 2289 | BM26: 4581 | BN26: 2128 | BO26: 2220 | BP26: 11451 | BQ26: 9963 | BR26: 4926 | BS26: 7843 | BT26: 20994 | BU26: 16539 | CE26: =IF(AND(AI26=0,BG26=0),"출시전",IF(AND(AI26=0,BG26>0),"미출고",AI26/BG26)) -> 출시전 | CF26: =IF(AND(AJ26=0,BH26=0),"출시전",IF(AND(AJ26=0,BH26>0),"미출고",AJ26/BH26)) -> 출시전 | CG26: =IF(AND(AK26=0,BI26=0),"출시전",IF(AND(AK26=0,BI26>0),"미출고",AK26/BI26)) -> 출시전 | CH26: =IF(AND(AL26=0,BJ26=0),"출시전",IF(AND(AL26=0,BJ26>0),"미출고",AL26/BJ26)) -> 출시전 | CI26: =IF(AND(AM26=0,BK26=0),"출시전",IF(AND(AM26=0,BK26>0),"미출고",AM26/BK26)) -> 출시전 | CJ26: =IF(AND(AN26=0,BL26=0),"출시전",IF(AND(AN26=0,BL26>0),"미출고",AN26/BL26)) -> 0.94408038 | CK26: =IF(AND(AO26=0,BM26=0),"출시전",IF(AND(AO26=0,BM26>0),"미출고",AO26/BM26)) -> 0.50556647 | CL26: =IF(AND(AP26=0,BN26=0),"출시전",IF(AND(AP26=0,BN26>0),"미출고",AP26/BN26)) -> 1.1884398 | ... CS26: =IF(AND(AW26=0,BU26=0),"출시전",IF(AND(AW26=0,BU26>0),"미출고",AW26/BU26)) -> 0.36338352
A27: 완제품 | B27: 340495 | C27: 리치 휘핑크림 서강유업 | D27: 1 | E27: =IFERROR(VLOOKUP(B27,재고DB!H:AS,38,FALSE),0) -> 2150 | F27: =SUMIF(재고DB!$H:$H,완제품!$B27,재고DB!$AB:$AB) -> 3804 | G27: =+E27*F27 -> 8178600 | H27: =IFERROR(VLOOKUP(B27,출고량!$A:$D,4,FALSE),0) -> 66 | I27: =IFERROR(F27/H27,0) -> 57.636364 | J27: =IF(F27=0,"재고없음",IF(H27=0,"출고없음",$H$1+I27*30)) -> 47532.091 | K27: =IF(F27=0,"재고없음",IFERROR(VLOOKUP(B27,재고DB!H:BU,66,FALSE),0)) -> 45952 | L27: =14+7 -> 21 | M27: =+L27+$H$1 -> 45824 | N27: 0.9 | O27: =IFERROR(IF(M27-J27>0,"O","X"),"없음") -> X | Q27: =+P27/D27*N27 -> 0 | R27: =IFERROR((Q27+F27)/H27*30+$H$1,"없음") -> 47532.091 | S27: =IFERROR(IF(J27="출고없음","X",IF(K27-J27>0,"O","X")),0) -> X | T27: =IF(J27="출고없음",$V$2,IF(I27=0,"-",IF(I27<=1,$S$2,IF(AND(I27>1,I27<=4),$T$2,$V$2)))) -> C | U27: =COUNTIF(CH27:CS27,"<0.1")+COUNTIF(CH27:CS27,"=미출고") -> 0 | V27: =IF(AND(S27="X",T27="C",U27>4),"단산검토",IF(AND(S27="X",T27="C"),"소진계획필요","판매활성화")) -> 소진계획필요 | AI27: 0 | AJ27: 0 | AK27: 0 | AL27: 0 | AM27: 0 | AN27: 0 | AO27: 0 | AP27: 0 | AQ27: 0 | AR27: 0 | AS27: 0 | AT27: 0 | AU27: 0 | AV27: 0 | AW27: 0 | AX27: 0 | BG27: 0 | BH27: 0 | BI27: 0 | BJ27: 0 | BK27: 0 | BL27: 0 | BM27: 0 | BN27: 0 | BO27: 0 | BP27: 0 | BQ27: 0 | BR27: 0 | BS27: 0 | BT27: 0 | BU27: 0 | CE27: =IF(AND(AI27=0,BG27=0),"출시전",IF(AND(AI27=0,BG27>0),"미출고",AI27/BG27)) -> 출시전 | CF27: =IF(AND(AJ27=0,BH27=0),"출시전",IF(AND(AJ27=0,BH27>0),"미출고",AJ27/BH27)) -> 출시전 | CG27: =IF(AND(AK27=0,BI27=0),"출시전",IF(AND(AK27=0,BI27>0),"미출고",AK27/BI27)) -> 출시전 | CH27: =IF(AND(AL27=0,BJ27=0),"출시전",IF(AND(AL27=0,BJ27>0),"미출고",AL27/BJ27)) -> 출시전 | CI27: =IF(AND(AM27=0,BK27=0),"출시전",IF(AND(AM27=0,BK27>0),"미출고",AM27/BK27)) -> 출시전 | CJ27: =IF(AND(AN27=0,BL27=0),"출시전",IF(AND(AN27=0,BL27>0),"미출고",AN27/BL27)) -> 출시전 | CK27: =IF(AND(AO27=0,BM27=0),"출시전",IF(AND(AO27=0,BM27>0),"미출고",AO27/BM27)) -> 출시전 | CL27: =IF(AND(AP27=0,BN27=0),"출시전",IF(AND(AP27=0,BN27>0),"미출고",AP27/BN27)) -> 출시전 | ... CS27: =IF(AND(AW27=0,BU27=0),"출시전",IF(AND(AW27=0,BU27>0),"미출고",AW27/BU27)) -> 출시전
A28: 완제품 | B28: 326263 | C28: 식물성 라이스 베이스드 | D28: 1 | E28: =IFERROR(VLOOKUP(B28,재고DB!H:AS,38,FALSE),0) -> 1718 | F28: =SUMIF(재고DB!$H:$H,완제품!$B28,재고DB!$AB:$AB) -> 6612 | G28: =+E28*F28 -> 11359416 | H28: =IFERROR(VLOOKUP(B28,출고량!$A:$D,4,FALSE),0) -> 10091.968 | I28: =IFERROR(F28/H28,0) -> 0.65517451 | J28: =IF(F28=0,"재고없음",IF(H28=0,"출고없음",$H$1+I28*30)) -> 45822.655 | K28: =IF(F28=0,"재고없음",IFERROR(VLOOKUP(B28,재고DB!H:BU,66,FALSE),0)) -> 46011 | L28: =7*5 -> 35 | M28: =+L28+$H$1 -> 45838 | N28: 0.9 | O28: =IFERROR(IF(M28-J28>0,"O","X"),"없음") -> O | P28: 15000 | Q28: =+P28/D28*N28 -> 13500 | R28: =IFERROR((Q28+F28)/H28*30+$H$1,"없음") -> 45862.786 | S28: =IFERROR(IF(J28="출고없음","X",IF(K28-J28>0,"O","X")),0) -> O | T28: =IF(J28="출고없음",$V$2,IF(I28=0,"-",IF(I28<=1,$S$2,IF(AND(I28>1,I28<=4),$T$2,$V$2)))) -> A | U28: =COUNTIF(CH28:CS28,"<0.1")+COUNTIF(CH28:CS28,"=미출고") -> 0 | V28: =IF(AND(S28="X",T28="C",U28>4),"단산검토",IF(AND(S28="X",T28="C"),"소진계획필요","판매활성화")) -> 판매활성화 | W28: 15000 | X28: 20000 | Y28: 20000 | AI28: 0 | AJ28: 0 | AK28: 0 | AL28: 0 | AM28: 0 | AN28: 0 | AO28: 980 | AP28: 5543 | AQ28: 17453 | AR28: 23926 | AS28: 17313 | AT28: 10761 | AU28: 9618 | AV28: 7974 | AW28: 11538 | AX28: 10412 | BG28: 0 | BH28: 0 | BI28: 0 | BJ28: 0 | BK28: 0 | BL28: 0 | BM28: 8643 | BN28: 14679 | BO28: 31543 | BP28: 23605 | BQ28: 23687 | BR28: 9782 | BS28: 11008 | BT28: 2442 | BU28: 6961 | CE28: =IF(AND(AI28=0,BG28=0),"출시전",IF(AND(AI28=0,BG28>0),"미출고",AI28/BG28)) -> 출시전 | CF28: =IF(AND(AJ28=0,BH28=0),"출시전",IF(AND(AJ28=0,BH28>0),"미출고",AJ28/BH28)) -> 출시전 | CG28: =IF(AND(AK28=0,BI28=0),"출시전",IF(AND(AK28=0,BI28>0),"미출고",AK28/BI28)) -> 출시전 | CH28: =IF(AND(AL28=0,BJ28=0),"출시전",IF(AND(AL28=0,BJ28>0),"미출고",AL28/BJ28)) -> 출시전 | CI28: =IF(AND(AM28=0,BK28=0),"출시전",IF(AND(AM28=0,BK28>0),"미출고",AM28/BK28)) -> 출시전 | CJ28: =IF(AND(AN28=0,BL28=0),"출시전",IF(AND(AN28=0,BL28>0),"미출고",AN28/BL28)) -> 출시전 | CK28: =IF(AND(AO28=0,BM28=0),"출시전",IF(AND(AO28=0,BM28>0),"미출고",AO28/BM28)) -> 0.11338656 | CL28: =IF(AND(AP28=0,BN28=0),"출시전",IF(AND(AP28=0,BN28>0),"미출고",AP28/BN28)) -> 0.37761428 | ... CS28: =IF(AND(AW28=0,BU28=0),"출시전",IF(AND(AW28=0,BU28>0),"미출고",AW28/BU28)) -> 1.6575205
A29: 완제품 | B29: 336755 | C29: 식물성 라이스 베이스드 BIB 10L | D29: 10 | E29: 17080 | F29: 1225 | G29: =+E29*F29 -> 20923000 | H29: =IFERROR(VLOOKUP(B29,출고량!$A:$D,4,FALSE),0) -> 315.87097 | I29: =IFERROR(F29/H29,0) -> 3.8781658 | J29: =IF(F29=0,"재고없음",IF(H29=0,"출고없음",$H$1+I29*30)) -> 45919.345 | K29: 46061 | L29: =7*5 -> 35 | M29: =+L29+$H$1 -> 45838 | N29: 0.9 | O29: =IFERROR(IF(M29-J29>0,"O","X"),"없음") -> X | P29: 17000 | Q29: =+P29/D29*N29 -> 1530 | R29: =IFERROR((Q29+F29)/H29*30+$H$1,"없음") -> 46064.657 | S29: =IFERROR(IF(J29="출고없음","X",IF(K29-J29>0,"O","X")),0) -> O | T29: =IF(J29="출고없음",$V$2,IF(I29=0,"-",IF(I29<=1,$S$2,IF(AND(I29>1,I29<=4),$T$2,$V$2)))) -> B | U29: =COUNTIF(CH29:CS29,"<0.1")+COUNTIF(CH29:CS29,"=미출고") -> 0 | V29: =IF(AND(S29="X",T29="C",U29>4),"단산검토",IF(AND(S29="X",T29="C"),"소진계획필요","판매활성화")) -> 판매활성화 | W29: 15000 | X29: 20000 | Z29: 20000 | AI29: 0 | AJ29: 0 | AK29: 0 | AL29: 0 | AM29: 0 | AN29: 0 | AO29: 0 | AP29: 0 | AQ29: 0 | AR29: 0 | AS29: 0 | AT29: 1360 | AU29: 1224 | AV29: 1224 | AW29: 1224 | AX29: 1224 | BG29: 0 | BH29: 0 | BI29: 0 | BJ29: 0 | BK29: 0 | BL29: 0 | BM29: 0 | BN29: 0 | BO29: 0 | BP29: 0 | BQ29: 0 | BR29: 936 | BS29: 2898 | BT29: 1745 | BU29: 2664 | CE29: =IF(AND(AI29=0,BG29=0),"출시전",IF(AND(AI29=0,BG29>0),"미출고",AI29/BG29)) -> 출시전 | CF29: =IF(AND(AJ29=0,BH29=0),"출시전",IF(AND(AJ29=0,BH29>0),"미출고",AJ29/BH29)) -> 출시전 | CG29: =IF(AND(AK29=0,BI29=0),"출시전",IF(AND(AK29=0,BI29>0),"미출고",AK29/BI29)) -> 출시전 | CH29: =IF(AND(AL29=0,BJ29=0),"출시전",IF(AND(AL29=0,BJ29>0),"미출고",AL29/BJ29)) -> 출시전 | CI29: =IF(AND(AM29=0,BK29=0),"출시전",IF(AND(AM29=0,BK29>0),"미출고",AM29/BK29)) -> 출시전 | CJ29: =IF(AND(AN29=0,BL29=0),"출시전",IF(AND(AN29=0,BL29>0),"미출고",AN29/BL29)) -> 출시전 | CK29: =IF(AND(AO29=0,BM29=0),"출시전",IF(AND(AO29=0,BM29>0),"미출고",AO29/BM29)) -> 출시전 | CL29: =IF(AND(AP29=0,BN29=0),"출시전",IF(AND(AP29=0,BN29>0),"미출고",AP29/BN29)) -> 출시전 | ... CS29: =IF(AND(AW29=0,BU29=0),"출시전",IF(AND(AW29=0,BU29>0),"미출고",AW29/BU29)) -> 0.45945946
A30: 완제품 | B30: 332805 | C30: 식물성 라이스 베이스드 200mL | D30: 0.2 | E30: =IFERROR(VLOOKUP(B30,재고DB!H:AS,38,FALSE),0)/24 -> 342 | F30: =SUMIF(재고DB!$H:$H,완제품!$B30,재고DB!$AB:$AB)*24 -> 64272 | G30: =+E30*F30 -> 21981024 | H30: =IFERROR(VLOOKUP(B30,출고량!$A:$D,4,FALSE),0) -> 14714.323 | I30: =IFERROR(F30/H30,0) -> 4.3679891 | J30: =IF(F30=0,"재고없음",IF(H30=0,"출고없음",$H$1+I30*30)) -> 45934.04 | K30: =IF(F30=0,"재고없음",IFERROR(VLOOKUP(B30,재고DB!H:BU,66,FALSE),0)) -> 46049 | L30: =7*5 -> 35 | M30: =+L30+$H$1 -> 45838 | N30: 0.85 | O30: =IFERROR(IF(M30-J30>0,"O","X"),"없음") -> X | P30: 20000 | Q30: =+P30/D30*N30 -> 85000 | R30: =IFERROR((Q30+F30)/H30*30+$H$1,"없음") -> 46107.34 | S30: =IFERROR(IF(J30="출고없음","X",IF(K30-J30>0,"O","X")),0) -> O | T30: =IF(J30="출고없음",$V$2,IF(I30=0,"-",IF(I30<=1,$S$2,IF(AND(I30>1,I30<=4),$T$2,$V$2)))) -> C | U30: =COUNTIF(CH30:CS30,"<0.1")+COUNTIF(CH30:CS30,"=미출고") -> 0 | V30: =IF(AND(S30="X",T30="C",U30>4),"단산검토",IF(AND(S30="X",T30="C"),"소진계획필요","판매활성화")) -> 판매활성화 | Z30: 15000 | AI30: 0 | AJ30: 0 | AK30: 0 | AL30: 0 | AM30: 0 | AN30: 0 | AO30: 0 | AP30: 0 | AQ30: =460*24 -> 11040 | AR30: =1551*24 -> 37224 | AS30: =1604*24 -> 38496 | AT30: 35688 | AU30: 22104 | AV30: 14952 | AW30: 15504 | AX30: 19632 | BG30: 0 | BH30: 0 | BI30: 0 | BJ30: 0 | BK30: 0 | BL30: 0 | BM30: 0 | BN30: 0 | BO30: =1128*24 -> 27072 | BP30: =2789*24 -> 66936 | BQ30: =1063*24 -> 25512 | BR30: 77760 | BS30: 52536 | BT30: 41592 | BU30: 25272 | CE30: =IF(AND(AI30=0,BG30=0),"출시전",IF(AND(AI30=0,BG30>0),"미출고",AI30/BG30)) -> 출시전 | CF30: =IF(AND(AJ30=0,BH30=0),"출시전",IF(AND(AJ30=0,BH30>0),"미출고",AJ30/BH30)) -> 출시전 | CG30: =IF(AND(AK30=0,BI30=0),"출시전",IF(AND(AK30=0,BI30>0),"미출고",AK30/BI30)) -> 출시전 | CH30: =IF(AND(AL30=0,BJ30=0),"출시전",IF(AND(AL30=0,BJ30>0),"미출고",AL30/BJ30)) -> 출시전 | CI30: =IF(AND(AM30=0,BK30=0),"출시전",IF(AND(AM30=0,BK30>0),"미출고",AM30/BK30)) -> 출시전 | CJ30: =IF(AND(AN30=0,BL30=0),"출시전",IF(AND(AN30=0,BL30>0),"미출고",AN30/BL30)) -> 출시전 | CK30: =IF(AND(AO30=0,BM30=0),"출시전",IF(AND(AO30=0,BM30>0),"미출고",AO30/BM30)) -> 출시전 | CL30: =IF(AND(AP30=0,BN30=0),"출시전",IF(AND(AP30=0,BN30>0),"미출고",AP30/BN30)) -> 출시전 | ... CS30: =IF(AND(AW30=0,BU30=0),"출시전",IF(AND(AW30=0,BU30>0),"미출고",AW30/BU30)) -> 0.61348528
A31: 완제품 | B31: 335472 | C31: 식물성 라이스 베이스드 200mL (낱개) | D31: 0.2 | E31: =+E30 -> 342 | F31: 0 | G31: 0 | H31: =IFERROR(VLOOKUP(B31,출고량!$A:$D,4,FALSE),0) -> 44.387097 | I31: =IFERROR(F31/H31,0) -> 0 | J31: =IF(F31=0,"재고없음",IF(H31=0,"출고없음",$H$1+I31*30)) -> 재고없음 | K31: =IF(F31=0,"재고없음",IFERROR(VLOOKUP(B31,재고DB!H:BU,66,FALSE),0)) -> 재고없음 | L31: 0 | M31: =+L31+$H$1 -> 45803 | O31: =IFERROR(IF(M31-J31>0,"O","X"),"없음") -> 없음 | P31: 0 | Q31: =+P31/D31*N31 -> 0 | R31: =IFERROR((Q31+F31)/H31*30+$H$1,"없음") -> 45803 | S31: =IFERROR(IF(J31="출고없음","X",IF(K31-J31>0,"O","X")),0) -> 0 | T31: =IF(J31="출고없음",$V$2,IF(I31=0,"-",IF(I31<=1,$S$2,IF(AND(I31>1,I31<=4),$T$2,$V$2)))) -> - | U31: =COUNTIF(CH31:CS31,"<0.1")+COUNTIF(CH31:CS31,"=미출고") -> 4 | V31: =IF(AND(S31="X",T31="C",U31>4),"단산검토",IF(AND(S31="X",T31="C"),"소진계획필요","판매활성화")) -> 판매활성화 | AI31: 0 | AJ31: 0 | AK31: 0 | AL31: 0 | AM31: 0 | AN31: 0 | AO31: 0 | AP31: 0 | AQ31: 0 | AR31: 5716 | AS31: 3447 | AT31: 858 | AU31: 305 | AV31: 197 | AW31: 221 | AX31: 172 | BG31: 0 | BH31: 0 | BI31: 0 | BJ31: 0 | BK31: 0 | BL31: 0 | BM31: 0 | BN31: 0 | BO31: =+BO30 -> 27072 | BP31: =+BP30 -> 66936 | BQ31: =+BQ30 -> 25512 | BR31: 77760 | BS31: =+BS30 -> 52536 | BT31: 0 | BU31: 0 | CE31: =IF(AND(AI31=0,BG31=0),"출시전",IF(AND(AI31=0,BG31>0),"미출고",AI31/BG31)) -> 출시전 | CF31: =IF(AND(AJ31=0,BH31=0),"출시전",IF(AND(AJ31=0,BH31>0),"미출고",AJ31/BH31)) -> 출시전 | CG31: =IF(AND(AK31=0,BI31=0),"출시전",IF(AND(AK31=0,BI31>0),"미출고",AK31/BI31)) -> 출시전 | CH31: =IF(AND(AL31=0,BJ31=0),"출시전",IF(AND(AL31=0,BJ31>0),"미출고",AL31/BJ31)) -> 출시전 | CI31: =IF(AND(AM31=0,BK31=0),"출시전",IF(AND(AM31=0,BK31>0),"미출고",AM31/BK31)) -> 출시전 | CJ31: =IF(AND(AN31=0,BL31=0),"출시전",IF(AND(AN31=0,BL31>0),"미출고",AN31/BL31)) -> 출시전 | CK31: =IF(AND(AO31=0,BM31=0),"출시전",IF(AND(AO31=0,BM31>0),"미출고",AO31/BM31)) -> 출시전 | CL31: =IF(AND(AP31=0,BN31=0),"출시전",IF(AND(AP31=0,BN31>0),"미출고",AP31/BN31)) -> 출시전 | ... CS31: =IF(AND(AW31=0,BU31=0),"출시전",IF(AND(AW31=0,BU31>0),"미출고",AW31/BU31)) -> #DIV/0!
A32: 반제품 | B32: 334969 | C32: BF M POWDER | D32: 4.305 | E32: 58694 | F32: 0 | G32: =+E32*F32 -> 0 | H32: =IFERROR(VLOOKUP(B32,출고량!$A:$D,4,FALSE),0) -> 0 | I32: =IFERROR(F32/H32,0) -> 0 | J32: =IF(F32=0,"재고없음",IF(H32=0,"출고없음",$H$1+I32*30)) -> 재고없음 | K32: =IF(F32=0,"재고없음",IFERROR(VLOOKUP(B32,재고DB!H:BU,66,FALSE),0)) -> 재고없음 | L32: 0 | M32: =+L32+$H$1 -> 45803 | O32: =IFERROR(IF(M32-J32>0,"O","X"),"없음") -> 없음 | P32: 0 | Q32: =+P32/D32*N32 -> 0 | R32: =IFERROR((Q32+F32)/H32*30+$H$1,"없음") -> 없음 | S32: =IFERROR(IF(J32="출고없음","X",IF(K32-J32>0,"O","X")),0) -> 0 | T32: =IF(J32="출고없음",$V$2,IF(I32=0,"-",IF(I32<=1,$S$2,IF(AND(I32>1,I32<=4),$T$2,$V$2)))) -> - | U32: =COUNTIF(CH32:CS32,"<0.1")+COUNTIF(CH32:CS32,"=미출고") -> 0 | V32: =IF(AND(S32="X",T32="C",U32>4),"단산검토",IF(AND(S32="X",T32="C"),"소진계획필요","판매활성화")) -> 판매활성화 | W32: =18*4.305 -> 77.49 | AV32: 0 | AW32: 0 | AX32: 0 | BT32: 0 | BU32: 0
A33: 완제품 | B33: 318446 | C33: 베러미트 콜드컷 식물성 볼로냐 슬라이스 수출 | D33: 0.5 | E33: 4800 | F33: =SUMIF(재고DB!$H:$H,완제품!$B33,재고DB!$AB:$AB) -> 0 | G33: =+E33*F33 -> 0 | H33: =IFERROR(VLOOKUP(B33,출고량!$A:$D,4,FALSE),0) -> 0 | I33: =IFERROR(F33/H33,0) -> 0 | J33: =IF(F33=0,"재고없음",IF(H33=0,"출고없음",$H$1+I33*30)) -> 재고없음 | K33: =IF(F33=0,"재고없음",IFERROR(VLOOKUP(B33,재고DB!H:BU,66,FALSE),0)) -> 재고없음 | L33: 28 | M33: =+L33+$H$1 -> 45831 | N33: 0.9 | O33: =IFERROR(IF(M33-J33>0,"O","X"),"없음") -> 없음 | P33: 0 | Q33: =+P33/D33*N33 -> 0 | R33: =IFERROR((Q33+F33)/H33*30+$H$1,"없음") -> 없음 | S33: =IFERROR(IF(J33="출고없음","X",IF(K33-J33>0,"O","X")),0) -> 0 | T33: =IF(J33="출고없음",$V$2,IF(I33=0,"-",IF(I33<=1,$S$2,IF(AND(I33>1,I33<=4),$T$2,$V$2)))) -> - | U33: =COUNTIF(CH33:CS33,"<0.1")+COUNTIF(CH33:CS33,"=미출고") -> 3 | V33: =IF(AND(S33="X",T33="C",U33>4),"단산검토",IF(AND(S33="X",T33="C"),"소진계획필요","판매활성화")) -> 판매활성화 | AI33: 0 | AJ33: 8000 | AK33: 0 | AL33: 2 | AM33: 0 | AN33: 0 | AO33: 0 | AP33: 0 | AQ33: 18 | AR33: 0 | AS33: 0 | AT33: 0 | AU33: 0 | AV33: 0 | AW33: 0 | AX33: 0 | BG33: 0 | BH33: 8020 | BI33: 20 | BJ33: 18 | BK33: 0 | BL33: 18 | BM33: 18 | BN33: 18 | BO33: 18 | BP33: 0 | BQ33: 0 | BR33: 0 | BS33: 0 | BT33: 0 | BU33: 0 | CE33: =IF(AND(AI33=0,BG33=0),"출시전",IF(AND(AI33=0,BG33>0),"미출고",AI33/BG33)) -> 출시전 | CF33: =IF(AND(AJ33=0,BH33=0),"출시전",IF(AND(AJ33=0,BH33>0),"미출고",AJ33/BH33)) -> 0.99750623 | CG33: =IF(AND(AK33=0,BI33=0),"출시전",IF(AND(AK33=0,BI33>0),"미출고",AK33/BI33)) -> 미출고 | CH33: =IF(AND(AL33=0,BJ33=0),"출시전",IF(AND(AL33=0,BJ33>0),"미출고",AL33/BJ33)) -> 0.11111111 | CI33: =IF(AND(AM33=0,BK33=0),"출시전",IF(AND(AM33=0,BK33>0),"미출고",AM33/BK33)) -> 출시전 | CJ33: =IF(AND(AN33=0,BL33=0),"출시전",IF(AND(AN33=0,BL33>0),"미출고",AN33/BL33)) -> 미출고 | CK33: =IF(AND(AO33=0,BM33=0),"출시전",IF(AND(AO33=0,BM33>0),"미출고",AO33/BM33)) -> 미출고 | CL33: =IF(AND(AP33=0,BN33=0),"출시전",IF(AND(AP33=0,BN33>0),"미출고",AP33/BN33)) -> 미출고 | ... CS33: =IF(AND(AW33=0,BU33=0),"출시전",IF(AND(AW33=0,BU33>0),"미출고",AW33/BU33)) -> 출시전
A34: 완제품 | B34: 326138 | C34: 유아왓유잇 식물성 미트볼 수출용 | D34: 1 | E34: =IFERROR(VLOOKUP(B34,재고DB!H:AS,38,FALSE),0) -> 0 | F34: =SUMIF(재고DB!$H:$H,완제품!$B34,재고DB!$AB:$AB) -> 0 | G34: =+E34*F34 -> 0 | H34: =IFERROR(VLOOKUP(B34,출고량!$A:$D,4,FALSE),0) -> 72.258065 | I34: =IFERROR(F34/H34,0) -> 0 | J34: =IF(F34=0,"재고없음",IF(H34=0,"출고없음",$H$1+I34*30)) -> 재고없음 | K34: =IF(F34=0,"재고없음",IFERROR(VLOOKUP(B34,재고DB!H:BU,66,FALSE),0)) -> 재고없음 | L34: 28 | M34: =+L34+$H$1 -> 45831 | N34: 0.95 | O34: =IFERROR(IF(M34-J34>0,"O","X"),"없음") -> 없음 | P34: 0 | Q34: =+P34/D34*N34 -> 0 | R34: =IFERROR((Q34+F34)/H34*30+$H$1,"없음") -> 45803 | S34: =IFERROR(IF(J34="출고없음","X",IF(K34-J34>0,"O","X")),0) -> 0 | T34: =IF(J34="출고없음",$V$2,IF(I34=0,"-",IF(I34<=1,$S$2,IF(AND(I34>1,I34<=4),$T$2,$V$2)))) -> - | U34: =COUNTIF(CH34:CS34,"<0.1")+COUNTIF(CH34:CS34,"=미출고") -> 8 | V34: =IF(AND(S34="X",T34="C",U34>4),"단산검토",IF(AND(S34="X",T34="C"),"소진계획필요","판매활성화")) -> 판매활성화 | AI34: 0 | AJ34: 0 | AK34: 0 | AL34: 0 | AM34: 640 | AN34: 0 | AO34: 0 | AP34: 0 | AQ34: 0 | AR34: 0 | AS34: 0 | AT34: 0 | AU34: 0 | AV34: 150 | AW34: 273 | AX34: 280 | BG34: 0 | BH34: 0 | BI34: 0 | BJ34: 0 | BK34: 1340 | BL34: 700 | BM34: 700 | BN34: 700 | BO34: 700 | BP34: 700 | BQ34: 700 | BR34: 700 | BS34: 700 | BT34: 550 | BU34: 277 | CE34: =IF(AND(AI34=0,BG34=0),"출시전",IF(AND(AI34=0,BG34>0),"미출고",AI34/BG34)) -> 출시전 | CF34: =IF(AND(AJ34=0,BH34=0),"출시전",IF(AND(AJ34=0,BH34>0),"미출고",AJ34/BH34)) -> 출시전 | CG34: =IF(AND(AK34=0,BI34=0),"출시전",IF(AND(AK34=0,BI34>0),"미출고",AK34/BI34)) -> 출시전 | CH34: =IF(AND(AL34=0,BJ34=0),"출시전",IF(AND(AL34=0,BJ34>0),"미출고",AL34/BJ34)) -> 출시전 | CI34: =IF(AND(AM34=0,BK34=0),"출시전",IF(AND(AM34=0,BK34>0),"미출고",AM34/BK34)) -> 0.47761194 | CJ34: =IF(AND(AN34=0,BL34=0),"출시전",IF(AND(AN34=0,BL34>0),"미출고",AN34/BL34)) -> 미출고 | CK34: =IF(AND(AO34=0,BM34=0),"출시전",IF(AND(AO34=0,BM34>0),"미출고",AO34/BM34)) -> 미출고 | CL34: =IF(AND(AP34=0,BN34=0),"출시전",IF(AND(AP34=0,BN34>0),"미출고",AP34/BN34)) -> 미출고 | ... CS34: =IF(AND(AW34=0,BU34=0),"출시전",IF(AND(AW34=0,BU34>0),"미출고",AW34/BU34)) -> 0.98555957
A35: 완제품 | B35: 325643 | C35: 유아왓유잇 식물성 민스 수출용 (단산) | D35: 4 | E35: =IFERROR(VLOOKUP(B35,재고DB!H:AS,38,FALSE),0) -> 0 | F35: =SUMIF(재고DB!$H:$H,완제품!$B35,재고DB!$AB:$AB) -> 0 | G35: =+E35*F35 -> 0 | H35: =IFERROR(VLOOKUP(B35,출고량!$A:$D,4,FALSE),0) -> 23.225806 | I35: =IFERROR(F35/H35,0) -> 0 | J35: =IF(F35=0,"재고없음",IF(H35=0,"출고없음",$H$1+I35*30)) -> 재고없음 | K35: =IF(F35=0,"재고없음",IFERROR(VLOOKUP(B35,재고DB!H:BU,66,FALSE),0)) -> 재고없음 | L35: 28 | M35: =+L35+$H$1 -> 45831 | N35: 0.95 | O35: =IFERROR(IF(M35-J35>0,"O","X"),"없음") -> 없음 | P35: 0 | Q35: =+P35/D35*N35 -> 0 | R35: =IFERROR((Q35+F35)/H35*30+$H$1,"없음") -> 45803 | S35: =IFERROR(IF(J35="출고없음","X",IF(K35-J35>0,"O","X")),0) -> 0 | T35: =IF(J35="출고없음",$V$2,IF(I35=0,"-",IF(I35<=1,$S$2,IF(AND(I35>1,I35<=4),$T$2,$V$2)))) -> - | U35: =COUNTIF(CH35:CS35,"<0.1")+COUNTIF(CH35:CS35,"=미출고") -> 8 | V35: =IF(AND(S35="X",T35="C",U35>4),"단산검토",IF(AND(S35="X",T35="C"),"소진계획필요","판매활성화")) -> 판매활성화 | AI35: 0 | AJ35: 0 | AK35: 0 | AL35: 0 | AM35: 3124 | AN35: 0 | AO35: 3510 | AP35: 0 | AQ35: 0 | AR35: 2 | AS35: 3 | AT35: 0 | AU35: 0 | AV35: 0 | AW35: 242 | AX35: 90 | BG35: 0 | BH35: 0 | BI35: 0 | BJ35: 0 | BK35: 3870 | BL35: 3870 | BM35: 360 | BN35: 360 | BO35: 360 | BP35: 358 | BQ35: 355 | BR35: 355 | BS35: 355 | BT35: 355 | BU35: 173 | CE35: =IF(AND(AI35=0,BG35=0),"출시전",IF(AND(AI35=0,BG35>0),"미출고",AI35/BG35)) -> 출시전 | CF35: =IF(AND(AJ35=0,BH35=0),"출시전",IF(AND(AJ35=0,BH35>0),"미출고",AJ35/BH35)) -> 출시전 | CG35: =IF(AND(AK35=0,BI35=0),"출시전",IF(AND(AK35=0,BI35>0),"미출고",AK35/BI35)) -> 출시전 | CH35: =IF(AND(AL35=0,BJ35=0),"출시전",IF(AND(AL35=0,BJ35>0),"미출고",AL35/BJ35)) -> 출시전 | CI35: =IF(AND(AM35=0,BK35=0),"출시전",IF(AND(AM35=0,BK35>0),"미출고",AM35/BK35)) -> 0.80723514 | CJ35: =IF(AND(AN35=0,BL35=0),"출시전",IF(AND(AN35=0,BL35>0),"미출고",AN35/BL35)) -> 미출고 | CK35: =IF(AND(AO35=0,BM35=0),"출시전",IF(AND(AO35=0,BM35>0),"미출고",AO35/BM35)) -> 9.75 | CL35: =IF(AND(AP35=0,BN35=0),"출시전",IF(AND(AP35=0,BN35>0),"미출고",AP35/BN35)) -> 미출고 | ... CS35: =IF(AND(AW35=0,BU35=0),"출시전",IF(AND(AW35=0,BU35>0),"미출고",AW35/BU35)) -> 1.3988439
